Workbook

Sheet raw_enrollment_data
A1: Record ID | B1: Practice Name | C1: Provider Name | D1: Individual NPI | E1: Group NPI | F1: Credentialed NPI | G1: Enrolled NPI | H1: Tax ID | I1: Payer Name | J1: Payer ID | K1: Payer Type | L1: PTAN / Provider Number | M1: Enrollment Type | N1: Credentialing Status | O1: Claims Enrollment Status | P1: ERA Enrollment Status | Q1: Clearinghouse Portal Updated | R1: Clearinghouse Configuration Status | S1: Submitted Date | T1: Approved Date | U1: Current Status | V1: Blocker Reason | W1: Assigned Owner | X1: Follow-up Date | Y1: Notes
A2: ENR-0001 | B2: Eastwood Pulmonary | C2: Dr. Rohan Menon | D2: IND-NPI-1001 | E2: GRP-NPI-9018 | F2: GRP-NPI-9018 | G2: GRP-NPI-9018 | H2: SYN-TIN-012 | I2: Medicaid | J2: MCD-OLD | K2: Government | L2: PTAN-0001 | M2: Claims | N2: Completed | O2: Rejected | P2: Not Required | Q2: Yes | R2: Issue Found | S2: 46145 | U2: Blocked | V2: Wrong payer ID | W2: nt92346 | X2: 46176 | Y2: Incorrect payer ID was used for enrollment or routing.
A3: ENR-0002 | B3: Cedar Grove Clinic | C3: Dr. Lily Scott | D3: IND-NPI-1002 | E3: GRP-NPI-9039 | F3: GRP-NPI-9039 | G3: GRP-NPI-9039 | H3: SYN-TIN-036 | I3: Medicare | J3: WRONG-MED | K3: Government | L3: PTAN-0002 | M3: Claims and ERA | N3: Completed | O3: Rejected | P3: Rejected | Q3: Yes | R3: Issue Found | S3: 46093 | U3: Blocked | V3: Wrong payer ID | W3: ew53009 | X3: 46183 | Y3: Incorrect payer ID was used for enrollment or routing.
A4: ENR-0003 | B4: Liberty Primary Care | C4: Dr. Asha Singh | D4: IND-NPI-1003 | E4: GRP-NPI-9011 | F4: GRP-NPI-9011 | G4: GRP-NPI-9011 | H4: SYN-TIN-012 | I4: Cigna | J4: CIG001 | K4: Commercial | L4: NA | M4: ERA | N4: Completed | O4: Not Required | P4: Pending | Q4: No | R4: Pending | S4: 46092 | U4: Pending | V4: Clearinghouse portal not updated | W4: nt92346 | X4: 46181 | Y4: Clearinghouse route or portal setup needs update before go-live.
A5: ENR-0004 | B5: Maple Leaf Urgent Care | C5: Dr. Emily Gray | D5: IND-NPI-1004 | E5: GRP-NPI-9023 | F5: GRP-NPI-9023 | G5: GRP-NPI-9023 | H5: SYN-TIN-011 | I5: United Healthcare | J5: UHC001 | K5: Commercial | L5: NA | M5: ERA | N5: Completed | O5: Not Required | P5: Approved | Q5: Yes | R5: Completed | S5: 46154 | T5: 46169 | U5: Ready | V5: No blocker | W5: rc48215 | X5: 46177 | Y5: Record is ready for expected transaction flow.
A6: ENR-0005 | B6: Sunrise Family Medicine | C6: Dr. Grace Das | D6: IND-NPI-1005 | E6: GRP-NPI-9041 | F6: GRP-NPI-9041 | G6: GRP-NPI-9041 | H6: SYN-TIN-006 | I6: United Healthcare | J6: UHC001 | K6: Commercial | L6: NA | M6: Claims and ERA | N6: Completed | O6: Approved | P6: Pending | Q6: No | R6: Pending | S6: 46086 | U6: Pending | V6: Clearinghouse portal not updated | W6: nt92346 | X6: 46187 | Y6: Clearinghouse route or portal setup needs update before go-live.
A7: ENR-0006 | B7: Coral Springs Primary Care | C7: Dr. Lily Singh | D7: IND-NPI-1006 | E7: GRP-NPI-9019 | F7: GRP-NPI-9019 | G7: GRP-NPI-9019 | H7: SYN-TIN-047 | I7: Medicare | J7: MED001 | K7: Government | L7: PTAN-0006 | M7: Claims and ERA | N7: Completed | O7: Pending | P7: Pending | Q7: Yes | R7: In Progress | S7: 46134 | U7: Pending | V7: Missing payer approval | W7: rc48215 | X7: 46180 | Y7: Waiting on payer approval or payer response.
A8: ENR-0007 | B8: BrightCare Cardiology | C8: Dr. Elena Gray | D8: IND-NPI-1007 | E8: GRP-NPI-9014 | F8: GRP-NPI-9014 | G8: GRP-NPI-9014 | H8: SYN-TIN-032 | I8: Cigna | J8: CIG001 | K8: Commercial | L8: NA | M8: ERA | N8: Completed | O8: Not Required | P8: Pending | Q8: Yes | R8: In Progress | S8: 46055 | U8: Pending | V8: ERA setup not completed | W8: nt00234 | X8: 46185 | Y8: ERA enrollment or routing is not fully completed.
A9: ENR-0008 | B9: BrightCare Cardiology | C9: Dr. Aria Kapoor | D9: IND-NPI-1008 | E9: GRP-NPI-9018 | F9: GRP-NPI-9018 | G9: GRP-NPI-9018 | H9: SYN-TIN-005 | I9: Cigna | J9: CIG001 | K9: Commercial | L9: NA | M9: Claims and ERA | N9: Completed | O9: Approved | P9: Approved | Q9: Yes | R9: Completed | S9: 46120 | T9: 46140 | U9: Ready | V9: No blocker | W9: nt00234 | X9: 46176 | Y9: Record is ready for expected transaction flow.
A10: ENR-0009 | B10: Liberty Primary Care | C10: Dr. Kevin Kapoor | D10: IND-NPI-1009 | E10: GRP-NPI-9018 | F10: GRP-NPI-9018 | G10: GRP-NPI-9018 | H10: SYN-TIN-051 | I10: Medicare | J10: MED001 | K10: Government | L10: PTAN-0009 | M10: Claims | N10: Completed | O10: Rejected | P10: Not Required | Q10: Yes | R10: In Progress | S10: 46117 | U10: Pending | V10: Medicare additional enrollment missing | W10: rc48215 | X10: 46179 | Y10: Medicare requires additional enrollment after credentialing.
A11: ENR-0010 | B11: Stonebridge Family Medicine | C11: Dr. Aria Wilson | D11: IND-NPI-1010 | E11: GRP-NPI-9017 | F11: GRP-NPI-9017 | G11: GRP-NPI-9017 | H11: SYN-TIN-047 | I11: Medicaid | J11: MCD002 | K11: Government | L11: PTAN-WRONG | M11: Claims | N11: Completed | O11: Rejected | P11: Not Required | Q11: Yes | R11: Issue Found | S11: 46146 | U11: Blocked | V11: Incorrect PTAN/provider number | W11: rc48215 | X11: 46185 | Y11: PTAN or government payer provider number needs correction.
A12: ENR-0011 | B12: Oak Street Primary Care | C12: Dr. Sara Scott | D12: IND-NPI-1011 | E12: GRP-NPI-9032 | F12: GRP-NPI-9032 | G12: GRP-NPI-9032 | H12: SYN-TIN-055 | I12: Medicare | J12: MED001 | K12: Government | L12: PTAN-0011 | M12: Claims and ERA | N12: Completed | O12: Pending | P12: Pending | Q12: Yes | R12: In Progress | S12: 46076 | U12: Pending | V12: Missing payer approval | W12: nt00234 | X12: 46186 | Y12: Waiting on payer approval or payer response.
A13: ENR-0012 | B13: Parkside Oncology | C13: Dr. Mark Kapoor | D13: IND-NPI-1012 | E13: GRP-NPI-9025 | F13: GRP-NPI-9025 | G13: GRP-NPI-9136 | H13: SYN-TIN-035 | I13: United Healthcare | J13: UHC001 | K13: Commercial | L13: NA | M13: Claims and ERA | N13: Completed | O13: Rejected | P13: Rejected | Q13: Yes | R13: Issue Found | S13: 46039 | U13: Blocked | V13: Credentialed NPI mismatch | W13: nt92346 | X13: 46186 | Y13: Enrolled NPI does not match the payer-credentialed NPI.
A14: ENR-0013 | B14: Clearwater Pulmonary | C14: Dr. Meera Shah | D14: IND-NPI-1013 | E14: GRP-NPI-9019 | F14: GRP-NPI-9019 | G14: GRP-NPI-9019 | H14: SYN-TIN-014 | I14: Aetna | J14: AET001 | K14: Commercial | L14: NA | M14: Claims | N14: Completed | O14: Approved | P14: Not Required | Q14: Yes | R14: Completed | S14: 46104 | T14: 46119 | U14: Ready | V14: No blocker | W14: ew53009 | X14: 46178 | Y14: Record is ready for expected transaction flow.
A15: ENR-0014 | B15: Harborview Pediatrics | C15: Dr. Farah Das | D15: IND-NPI-1014 | E15: GRP-NPI-9041 | F15: GRP-NPI-9041 | G15: GRP-NPI-9041 | H15: SYN-TIN-042 | I15: United Healthcare | J15: UHC001 | K15: Commercial | L15: NA | M15: Claims and ERA | N15: Completed | O15: Approved | P15: Approved | Q15: Yes | R15: Completed | S15: 46078 | T15: 46093 | U15: Ready | V15: No blocker | W15: nt92346 | X15: 46184 | Y15: Record is ready for expected transaction flow.
A16: ENR-0015 | B16: Valley View Gastro | C16: Dr. Neha Shah | D16: IND-NPI-1015 | E16: GRP-NPI-9024 | F16: GRP-NPI-9024 | G16: GRP-NPI-9024 | H16: SYN-TIN-063 | I16: Humana | J16: HUM001 | K16: Commercial | L16: NA | M16: Claims and ERA | N16: Completed | O16: Approved | P16: Approved | Q16: Yes | R16: Completed | S16: 46098 | T16: 46114 | U16: Ready | V16: No blocker | W16: nt92346 | X16: 46177 | Y16: Record is ready for expected transaction flow.
A17: ENR-0016 | B17: Evergreen Urology | C17: Dr. Mark Singh | D17: IND-NPI-1016 | E17: GRP-NPI-9035 | F17: GRP-NPI-9035 | G17: GRP-NPI-9035 | H17: SYN-TIN-055 | I17: Humana | J17: HUM001 | K17: Commercial | L17: NA | M17: Claims | N17: In Progress | O17: Not Started | P17: Not Required | Q17: No | R17: Not Started | S17: 46079 | U17: Pending | V17: Credentialing not completed | W17: ew53009 | X17: 46180 | Y17: Credentialing must be completed before enrollment can proceed.
A18: ENR-0017 | B18: Cedar Grove Clinic | C18: Dr. Samir Singh | D18: IND-NPI-1017 | E18: GRP-NPI-9045 | F18: GRP-NPI-9045 | G18: IND-NPI-1017 | H18: SYN-TIN-058 | I18: Medicaid | J18: MCD002 | K18: Government | L18: PTAN-0017 | M18: Claims and ERA | N18: Completed | O18: Rejected | P18: Rejected | Q18: Yes | R18: Issue Found | S18: 46132 | U18: Blocked | V18: Individual NPI used instead of group NPI | W18: ew53009 | X18: 46183 | Y18: Enrollment was submitted under individual NPI instead of group billing NPI.
A19: ENR-0018 | B19: Lakeside Women Health | C19: Dr. Sanjay Patel | D19: IND-NPI-1018 | E19: GRP-NPI-9005 | F19: GRP-NPI-9005 | G19: GRP-NPI-9138 | H19: SYN-TIN-008 | I19: Blue Cross | J19: BCBS01 | K19: Commercial | L19: NA | M19: Claims | N19: Completed | O19: Rejected | P19: Not Required | Q19: Yes | R19: Issue Found | S19: 46093 | U19: Blocked | V19: Credentialed NPI mismatch | W19: nt92346 | X19: 46176 | Y19: Enrolled NPI does not match the payer-credentialed NPI.
A20: ENR-0019 | B20: Oak Street Primary Care | C20: Dr. Mark Nguyen | D20: IND-NPI-1019 | E20: GRP-NPI-9003 | F20: GRP-NPI-9003 | G20: IND-NPI-1019 | H20: SYN-TIN-028 | I20: Humana | J20: HUM001 | K20: Commercial | L20: NA | M20: ERA | N20: Completed | O20: Not Required | P20: Rejected | Q20: Yes | R20: Issue Found | S20: 46108 | U20: Blocked | V20: Individual NPI used instead of group NPI | W20: rc48215 | X20: 46186 | Y20: Enrollment was submitted under individual NPI instead of group billing NPI.
A21: ENR-0020 | B21: Sunrise Family Medicine | C21: Dr. Sara Torres | D21: IND-NPI-1020 | E21: GRP-NPI-9037 | F21: GRP-NPI-9037 | G21: GRP-NPI-9037 | H21: SYN-TIN-056 | I21: United Healthcare | J21: WRONG-UHC | K21: Commercial | L21: NA | M21: Claims and ERA | N21: Completed | O21: Rejected | P21: Rejected | Q21: Yes | R21: Issue Found | S21: 46085 | U21: Blocked | V21: Wrong payer ID | W21: nt92346 | X21: 46177 | Y21: Incorrect payer ID was used for enrollment or routing.
A22: ENR-0021 | B22: Silverline Neurology | C22: Dr. Ethan Ali | D22: IND-NPI-1021 | E22: GRP-NPI-9030 | F22: GRP-NPI-9030 | G22: GRP-NPI-9030 | H22: SYN-TIN-044 | I22: Humana | J22: HUM001 | K22: Commercial | L22: NA | M22: Claims and ERA | N22: In Progress | O22: Not Started | P22: Not Started | Q22: No | R22: Not Started | S22: 46062 | U22: Pending | V22: Credentialing not completed | W22: rc48215 | X22: 46176 | Y22: Credentialing must be completed before enrollment can proceed.
A23: ENR-0022 | B23: Liberty Primary Care | C23: Dr. Emily Patel | D23: IND-NPI-1022 | E23: GRP-NPI-9013 | F23: GRP-NPI-9013 | G23: GRP-NPI-9013 | H23: SYN-TIN-010 | I23: Medicaid | J23: MCD002 | K23: Government | L23: PTAN-0022 | M23: Claims and ERA | N23: Completed | O23: Approved | P23: Approved | Q23: Yes | R23: Completed | S23: 46083 | T23: 46094 | U23: Ready | V23: No blocker | W23: nt00234 | X23: 46183 | Y23: Record is ready for expected transaction flow.
A24: ENR-0023 | B24: Blue Harbor ENT | C24: Dr. Ivy Shah | D24: IND-NPI-1023 | E24: GRP-NPI-9004 | F24: GRP-NPI-9004 | G24: GRP-NPI-9004 | H24: SYN-TIN-063 | I24: Cigna | J24: CIG-OLD | K24: Commercial | L24: NA | M24: Claims and ERA | N24: Completed | O24: Rejected | P24: Rejected | Q24: Yes | R24: Issue Found | S24: 46097 | U24: Blocked | V24: Old payer ID used | W24: rc48215 | X24: 46178 | Y24: Outdated payer ID needs to be replaced with current payer ID.
A25: ENR-0024 | B25: Valley View Gastro | C25: Dr. Omar Carter | D25: IND-NPI-1024 | E25: GRP-NPI-9026 | F25: GRP-NPI-9026 | G25: GRP-NPI-9026 | H25: SYN-TIN-055 | I25: Medicare | J25: MED001 | K25: Government | L25: PTAN-0024 | M25: Claims | N25: Completed | O25: Approved | P25: Not Required | Q25: Yes | R25: Completed | S25: 46136 | T25: 46147 | U25: Ready | V25: No blocker | W25: k19731 | X25: 46183 | Y25: Record is ready for expected transaction flow.
A26: ENR-0025 | B26: Grand Oak Surgery Center | C26: Dr. Ivy Joshi | D26: IND-NPI-1025 | E26: GRP-NPI-9032 | F26: GRP-NPI-9032 | G26: GRP-NPI-9032 | H26: SYN-TIN-008 | I26: Medicaid | J26: MCD002 | K26: Government | L26: PTAN-0025 | M26: Claims | N26: Completed | O26: Approved | P26: Not Required | Q26: Yes | R26: Completed | S26: 46051 | T26: 46067 | U26: Ready | V26: No blocker | W26: ew53009 | X26: 46187 | Y26: Record is ready for expected transaction flow.
A27: ENR-0026 | B27: Willow Creek Pediatrics | C27: Dr. Kevin Rao | D27: IND-NPI-1026 | E27: GRP-NPI-9004 | F27: GRP-NPI-9004 | G27: GRP-NPI-9004 | H27: SYN-TIN-011 | I27: United Healthcare | J27: UHC001 | K27: Commercial | L27: NA | M27: Claims and ERA | N27: Completed | O27: Pending | P27: Pending | Q27: Yes | R27: In Progress | S27: 46172 | U27: Pending | V27: Missing payer approval | W27: nt92346 | X27: 46178 | Y27: Waiting on payer approval or payer response.
A28: ENR-0027 | B28: Harborview Pediatrics | C28: Dr. Thomas Lee | D28: IND-NPI-1027 | E28: GRP-NPI-9039 | F28: GRP-NPI-9039 | G28: GRP-NPI-9039 | H28: SYN-TIN-006 | I28: Medicare | J28: MED001 | K28: Government | L28: PTAN-0027 | M28: Claims and ERA | N28: Completed | O28: Approved | P28: Approved | Q28: Yes | R28: Completed | S28: 46067 | T28: 46083 | U28: Ready | V28: No blocker | W28: ew53009 | X28: 46179 | Y28: Record is ready for expected transaction flow.
A29: ENR-0028 | B29: Parkside Oncology | C29: Dr. Vivek Ali | D29: IND-NPI-1028 | E29: GRP-NPI-9043 | F29: GRP-NPI-9043 | G29: GRP-NPI-9043 | H29: SYN-TIN-031 | I29: United Healthcare | J29: UHC001 | K29: Commercial | L29: NA | M29: Claims and ERA | N29: Completed | O29: Approved | P29: Pending | Q29: No | R29: Pending | S29: 46103 | U29: Pending | V29: Clearinghouse portal not updated | W29: k19731 | X29: 46179 | Y29: Clearinghouse route or portal setup needs update before go-live.
A30: ENR-0029 | B30: Westbrook Dermatology | C30: Dr. Noah Wilson | D30: IND-NPI-1029 | E30: GRP-NPI-9043 | F30: GRP-NPI-9043 | G30: GRP-NPI-9043 | H30: SYN-TIN-013 | I30: Cigna | J30: CIG001 | K30: Commercial | L30: NA | M30: ERA | N30: Completed | O30: Not Required | P30: Pending | Q30: No | R30: Pending | S30: 46055 | U30: Pending | V30: Clearinghouse portal not updated | W30: rc48215 | X30: 46176 | Y30: Clearinghouse route or portal setup needs update before go-live.
A31: ENR-0030 | B31: Greenway Internal Medicine | C31: Dr. Samir Chen | D31: IND-NPI-1030 | E31: GRP-NPI-9033 | F31: GRP-NPI-9033 | G31: GRP-NPI-9033 | H31: SYN-TIN-037 | I31: Blue Cross | J31: BCBS01 | K31: Commercial | L31: NA | M31: Claims | N31: Completed | O31: Approved | P31: Not Required | Q31: No | R31: Pending | S31: 46054 | U31: Pending | V31: Clearinghouse portal not updated | W31: k19731 | X31: 46179 | Y31: Clearinghouse route or portal setup needs update before go-live.
A32: ENR-0031 | B32: BrightCare Cardiology | C32: Dr. Leah Das | D32: IND-NPI-1031 | E32: GRP-NPI-9035 | F32: GRP-NPI-9035 | G32: GRP-NPI-9035 | H32: SYN-TIN-039 | I32: Cigna | J32: CIG001 | K32: Commercial | L32: NA | M32: ERA | N32: Completed | O32: Not Required | P32: Pending | Q32: Yes | R32: In Progress | S32: 46172 | U32: Pending | V32: ERA setup not completed | W32: ew53009 | X32: 46176 | Y32: ERA enrollment or routing is not fully completed.
A33: ENR-0032 | B33: Canyon Ridge Clinic | C33: Dr. Emily Nguyen | D33: IND-NPI-1032 | E33: GRP-NPI-9009 | F33: GRP-NPI-9009 | G33: GRP-NPI-9009 | H33: SYN-TIN-027 | I33: Blue Cross | J33: BCBS01 | K33: Commercial | L33: NA | M33: Claims | N33: Completed | O33: Approved | P33: Not Required | Q33: Yes | R33: Completed | S33: 46076 | T33: 46087 | U33: Ready | V33: No blocker | W33: ew53009 | X33: 46180 | Y33: Record is ready for expected transaction flow.
A34: ENR-0033 | B34: Grand Oak Surgery Center | C34: Dr. Meera Chen | D34: IND-NPI-1033 | E34: GRP-NPI-9044 | F34: GRP-NPI-9044 | G34: IND-NPI-1033 | H34: SYN-TIN-055 | I34: Cigna | J34: CIG001 | K34: Commercial | L34: NA | M34: Claims and ERA | N34: Completed | O34: Rejected | P34: Rejected | Q34: Yes | R34: Issue Found | S34: 46101 | U34: Blocked | V34: Individual NPI used instead of group NPI | W34: nt92346 | X34: 46176 | Y34: Enrollment was submitted under individual NPI instead of group billing NPI.
A35: ENR-0034 | B35: Evergreen Urology | C35: Dr. Aditya Rao | D35: IND-NPI-1034 | E35: GRP-NPI-9001 | F35: GRP-NPI-9001 | G35: GRP-NPI-9001 | H35: SYN-TIN-055 | I35: Blue Cross | J35: BCBS01 | K35: Commercial | L35: NA | M35: Claims and ERA | N35: Completed | O35: Rejected | P35: Rejected | Q35: Yes | R35: Issue Found | S35: 46104 | U35: Blocked | V35: Incorrect PTAN/provider number | W35: rc48215 | X35: 46178 | Y35: PTAN or government payer provider number needs correction.
A36: ENR-0035 | B36: Sunrise Family Medicine | C36: Dr. Asha Shah | D36: IND-NPI-1035 | E36: GRP-NPI-9005 | F36: GRP-NPI-9005 | G36: GRP-NPI-9124 | H36: SYN-TIN-006 | I36: Cigna | J36: CIG001 | K36: Commercial | L36: NA | M36: Claims and ERA | N36: Completed | O36: Rejected | P36: Rejected | Q36: Yes | R36: Issue Found | S36: 46074 | U36: Blocked | V36: Credentialed NPI mismatch | W36: nt00234 | X36: 46182 | Y36: Enrolled NPI does not match the payer-credentialed NPI.
A37: ENR-0036 | B37: Summit Eye Care | C37: Dr. Elena Nguyen | D37: IND-NPI-1036 | E37: GRP-NPI-9003 | F37: GRP-NPI-9003 | G37: GRP-NPI-9003 | H37: SYN-TIN-020 | I37: Blue Cross | J37: BCBS01 | K37: Commercial | L37: NA | M37: Claims | N37: Completed | O37: Approved | P37: Not Required | Q37: Yes | R37: Completed | S37: 46063 | T37: 46075 | U37: Ready | V37: No blocker | W37: rc48215 | X37: 46184 | Y37: Record is ready for expected transaction flow.
A38: ENR-0037 | B38: Canyon Ridge Clinic | C38: Dr. Sanjay Carter | D38: IND-NPI-1037 | E38: GRP-NPI-9011 | F38: GRP-NPI-9011 | G38: GRP-NPI-9011 | H38: SYN-TIN-053 | I38: Humana | J38: HUM001 | K38: Commercial | L38: NA | M38: Claims and ERA | N38: Completed | O38: Pending | P38: Pending | Q38: Yes | R38: In Progress | S38: 46043 | U38: Pending | V38: Missing payer approval | W38: k19731 | X38: 46178 | Y38: Waiting on payer approval or payer response.
A39: ENR-0038 | B39: Liberty Primary Care | C39: Dr. Sanjay Khan | D39: IND-NPI-1038 | E39: GRP-NPI-9011 | F39: GRP-NPI-9011 | G39: GRP-NPI-9011 | H39: SYN-TIN-026 | I39: Humana | J39: HUM001 | K39: Commercial | L39: NA | M39: Claims and ERA | N39: Completed | O39: Approved | P39: Pending | Q39: No | R39: Pending | S39: 46046 | U39: Pending | V39: Clearinghouse portal not updated | W39: nt00234 | X39: 46183 | Y39: Clearinghouse route or portal setup needs update before go-live.
A40: ENR-0039 | B40: Evergreen Urology | C40: Dr. Aria Gray | D40: IND-NPI-1039 | E40: GRP-NPI-9020 | F40: GRP-NPI-9020 | G40: GRP-NPI-9020 | H40: SYN-TIN-043 | I40: Humana | J40: HUM001 | K40: Commercial | L40: NA | M40: Claims and ERA | N40: Completed | O40: Approved | P40: Approved | Q40: Yes | R40: Completed | S40: 46043 | T40: 46060 | U40: Ready | V40: No blocker | W40: rc48215 | X40: 46179 | Y40: Record is ready for expected transaction flow.
...

Sheet working_clean_data
A1: Record ID | B1: Practice Name | C1: Provider Name | D1: Individual NPI | E1: Group NPI | F1: Credentialed NPI | G1: Enrolled NPI | H1: Tax ID | I1: Payer Name | J1: Payer ID | K1: Payer Type | L1: PTAN / Provider Number | M1: Enrollment Type | N1: Credentialing Status | O1: Claims Enrollment Status | P1: ERA Enrollment Status | Q1: Clearinghouse Portal Updated | R1: Clearinghouse Configuration Status | S1: Submitted Date | T1: Approved Date | U1: Current Status | V1: Blocker Reason | W1: Assigned Owner | X1: Follow-up Date | Y1: Notes | Z1: Aging Days | AA1: SLA Status | AB1: NPI Match Status | AC1: Provider Identifier Issue Flag | AD1: Payer Routing issue Flag | AE1: Clearinghouse gap Flag | AF1: Government Payer Issue Flag | AG1: Claims Ready Flag | AH1: ERA Ready Flag | AI1: Action Required Flag | AK1: Total Records | AL1: =ROWS(tblEnrollment[Record ID]) -> 250
A2: ENR-0001 | B2: Eastwood Pulmonary | C2: Dr. Rohan Menon | D2: IND-NPI-1001 | E2: GRP-NPI-9018 | F2: GRP-NPI-9018 | G2: GRP-NPI-9018 | H2: SYN-TIN-012 | I2: Medicaid | J2: MCD-OLD | K2: Government | L2: PTAN-0001 | M2: Claims | N2: Completed | O2: Rejected | P2: Not Required | Q2: Yes | R2: Issue Found | S2: 46145 | U2: Blocked | V2: Wrong payer ID | W2: nt92346 | X2: 46176 | Y2: Incorrect payer ID was used for enrollment or routing. | Z2: =IF(tblEnrollment[[#This Row],[Approved Date]]="",DATE(2026,6,3)-tblEnrollment[[#This Row],[Submitted Date]],tblEnrollment[[#This Row],[Approved Date]]-tblEnrollment[[#This Row],[Submitted Date]]) -> 31 | AA2: =IF(tblEnrollment[[#This Row],[Current Status]] ="Ready","Completed",IF(Z2>21,"SLA Breached","Within SLA")) -> SLA Breached | AB2: =IF(tblEnrollment[[#This Row],[Credentialed NPI]] =tblEnrollment[[#This Row],[Enrolled NPI]],"NPI Match","NPI Mismatch") -> NPI Match | AC2: =IF(OR(tblEnrollment[[#This Row],[Blocker Reason]] ="Individual NPI used instead of Group NPI",tblEnrollment[[#This Row],[Blocker Reason]] ="Credentialed NPI mismatch",tblEnrollment[[#This Row],[Blocker Reason]] ="Incorrect PTAN/Provider number"),"Yes","No") -> No | AD2: =IF(OR(tblEnrollment[[#This Row],[Blocker Reason]] ="Wrong Payer ID",tblEnrollment[[#This Row],[Blocker Reason]] ="Old Payer ID used"),"Yes","No") -> Yes | AE2: =IF(OR(tblEnrollment[[#This Row],[Clearinghouse Portal Updated]]="No",tblEnrollment[[#This Row],[Blocker Reason]] ="Clearinghouse portal not updated"),"Yes","No") -> No | AF2: =IF(OR(tblEnrollment[[#This Row],[Blocker Reason]] ="Medicaid additional enrollment missing",tblEnrollment[Blocker Reason]="Medicaid requires additional enrollment after credentialing.",tblEnrollment[[#This Row],[Blocker Reason]] ="Incorrect PTAN/Provider number",tblEnrollment[[#This Row],[Blocker Reason]] ="Medicare additional enrollment missing"),"Yes","No") -> No | AG2: =IF(OR(tblEnrollment[[#This Row],[Enrollment Type]]="Claims",tblEnrollment[[#This Row],[Enrollment Type]]="Claims and ERA"),IF(AND(tblEnrollment[[#This Row],[Credentialing Status]]="Completed",tblEnrollment[[#This Row],[Claims Enrollment Status]]="Approved",tblEnrollment[[#This Row],[Clearinghouse Configuration Status]]="Completed",AB2="NPI Match"),"Ready","Not Ready"),"Not Applicable") -> Not Ready | AH2: =IF(OR(tblEnrollment[[#This Row],[Enrollment Type]]="ERA",tblEnrollment[[#This Row],[Enrollment Type]]="Claims and ERA"),IF(AND(tblEnrollment[[#This Row],[Credentialing Status]]="Completed",tblEnrollment[[#This Row],[ERA Enrollment Status]]="Approved",tblEnrollment[[#This Row],[Clearinghouse Configuration Status]]="Completed",AB2="NPI Match"),"Ready","Not Ready"),"Not Applicable") -> Not Applicable | AI2: =IF(tblEnrollment[[#This Row],[Blocker Reason]] ="No Blocker","No","Yes") -> Yes | AK2: Records over 21 days | AL2: =COUNTIFS(tblEnrollment[Aging Days],">21",tblEnrollment[Current Status],"<>Ready") -> 158
A3: ENR-0002 | B3: Cedar Grove Clinic | C3: Dr. Lily Scott | D3: IND-NPI-1002 | E3: GRP-NPI-9039 | F3: GRP-NPI-9039 | G3: GRP-NPI-9039 | H3: SYN-TIN-036 | I3: Medicare | J3: WRONG-MED | K3: Government | L3: PTAN-0002 | M3: Claims and ERA | N3: Completed | O3: Rejected | P3: Rejected | Q3: Yes | R3: Issue Found | S3: 46093 | U3: Blocked | V3: Wrong payer ID | W3: ew53009 | X3: 46183 | Y3: Incorrect payer ID was used for enrollment or routing. | Z3: =IF(tblEnrollment[[#This Row],[Approved Date]]="",DATE(2026,6,3)-tblEnrollment[[#This Row],[Submitted Date]],tblEnrollment[[#This Row],[Approved Date]]-tblEnrollment[[#This Row],[Submitted Date]]) -> 83 | AA3: =IF(tblEnrollment[[#This Row],[Current Status]] ="Ready","Completed",IF(Z3>21,"SLA Breached","Within SLA")) -> SLA Breached | AB3: =IF(tblEnrollment[[#This Row],[Credentialed NPI]] =tblEnrollment[[#This Row],[Enrolled NPI]],"NPI Match","NPI Mismatch") -> NPI Match | AC3: =IF(OR(tblEnrollment[[#This Row],[Blocker Reason]] ="Individual NPI used instead of Group NPI",tblEnrollment[[#This Row],[Blocker Reason]] ="Credentialed NPI mismatch",tblEnrollment[[#This Row],[Blocker Reason]] ="Incorrect PTAN/Provider number"),"Yes","No") -> No | AD3: =IF(OR(tblEnrollment[[#This Row],[Blocker Reason]] ="Wrong Payer ID",tblEnrollment[[#This Row],[Blocker Reason]] ="Old Payer ID used"),"Yes","No") -> Yes | AE3: =IF(OR(tblEnrollment[[#This Row],[Clearinghouse Portal Updated]]="No",tblEnrollment[[#This Row],[Blocker Reason]] ="Clearinghouse portal not updated"),"Yes","No") -> No | AF3: =IF(OR(tblEnrollment[[#This Row],[Blocker Reason]] ="Medicaid additional enrollment missing",tblEnrollment[Blocker Reason]="Medicaid requires additional enrollment after credentialing.",tblEnrollment[[#This Row],[Blocker Reason]] ="Incorrect PTAN/Provider number",tblEnrollment[[#This Row],[Blocker Reason]] ="Medicare additional enrollment missing"),"Yes","No") -> No | AG3: =IF(OR(tblEnrollment[[#This Row],[Enrollment Type]]="Claims",tblEnrollment[[#This Row],[Enrollment Type]]="Claims and ERA"),IF(AND(tblEnrollment[[#This Row],[Credentialing Status]]="Completed",tblEnrollment[[#This Row],[Claims Enrollment Status]]="Approved",tblEnrollment[[#This Row],[Clearinghouse Configuration Status]]="Completed",AB3="NPI Match"),"Ready","Not Ready"),"Not Applicable") -> Not Ready | AH3: =IF(OR(tblEnrollment[[#This Row],[Enrollment Type]]="ERA",tblEnrollment[[#This Row],[Enrollment Type]]="Claims and ERA"),IF(AND(tblEnrollment[[#This Row],[Credentialing Status]]="Completed",tblEnrollment[[#This Row],[ERA Enrollment Status]]="Approved",tblEnrollment[[#This Row],[Clearinghouse Configuration Status]]="Completed",AB3="NPI Match"),"Ready","Not Ready"),"Not Applicable") -> Not Ready | AI3: =IF(tblEnrollment[[#This Row],[Blocker Reason]] ="No Blocker","No","Yes") -> Yes | AK3: Blank Record IDs | AL3: =COUNTBLANK(tblEnrollment[Record ID]) -> 0
A4: ENR-0003 | B4: Liberty Primary Care | C4: Dr. Asha Singh | D4: IND-NPI-1003 | E4: GRP-NPI-9011 | F4: GRP-NPI-9011 | G4: GRP-NPI-9011 | H4: SYN-TIN-012 | I4: Cigna | J4: CIG001 | K4: Commercial | L4: NA | M4: ERA | N4: Completed | O4: Not Required | P4: Pending | Q4: No | R4: Pending | S4: 46092 | U4: Pending | V4: Clearinghouse portal not updated | W4: nt92346 | X4: 46181 | Y4: Clearinghouse route or portal setup needs update before go-live. | Z4: =IF(tblEnrollment[[#This Row],[Approved Date]]="",DATE(2026,6,3)-tblEnrollment[[#This Row],[Submitted Date]],tblEnrollment[[#This Row],[Approved Date]]-tblEnrollment[[#This Row],[Submitted Date]]) -> 84 | AA4: =IF(tblEnrollment[[#This Row],[Current Status]] ="Ready","Completed",IF(Z4>21,"SLA Breached","Within SLA")) -> SLA Breached | AB4: =IF(tblEnrollment[[#This Row],[Credentialed NPI]] =tblEnrollment[[#This Row],[Enrolled NPI]],"NPI Match","NPI Mismatch") -> NPI Match | AC4: =IF(OR(tblEnrollment[[#This Row],[Blocker Reason]] ="Individual NPI used instead of Group NPI",tblEnrollment[[#This Row],[Blocker Reason]] ="Credentialed NPI mismatch",tblEnrollment[[#This Row],[Blocker Reason]] ="Incorrect PTAN/Provider number"),"Yes","No") -> No | AD4: =IF(OR(tblEnrollment[[#This Row],[Blocker Reason]] ="Wrong Payer ID",tblEnrollment[[#This Row],[Blocker Reason]] ="Old Payer ID used"),"Yes","No") -> No | AE4: =IF(OR(tblEnrollment[[#This Row],[Clearinghouse Portal Updated]]="No",tblEnrollment[[#This Row],[Blocker Reason]] ="Clearinghouse portal not updated"),"Yes","No") -> Yes | AF4: =IF(OR(tblEnrollment[[#This Row],[Blocker Reason]] ="Medicaid additional enrollment missing",tblEnrollment[Blocker Reason]="Medicaid requires additional enrollment after credentialing.",tblEnrollment[[#This Row],[Blocker Reason]] ="Incorrect PTAN/Provider number",tblEnrollment[[#This Row],[Blocker Reason]] ="Medicare additional enrollment missing"),"Yes","No") -> No | AG4: =IF(OR(tblEnrollment[[#This Row],[Enrollment Type]]="Claims",tblEnrollment[[#This Row],[Enrollment Type]]="Claims and ERA"),IF(AND(tblEnrollment[[#This Row],[Credentialing Status]]="Completed",tblEnrollment[[#This Row],[Claims Enrollment Status]]="Approved",tblEnrollment[[#This Row],[Clearinghouse Configuration Status]]="Completed",AB4="NPI Match"),"Ready","Not Ready"),"Not Applicable") -> Not Applicable | AH4: =IF(OR(tblEnrollment[[#This Row],[Enrollment Type]]="ERA",tblEnrollment[[#This Row],[Enrollment Type]]="Claims and ERA"),IF(AND(tblEnrollment[[#This Row],[Credentialing Status]]="Completed",tblEnrollment[[#This Row],[ERA Enrollment Status]]="Approved",tblEnrollment[[#This Row],[Clearinghouse Configuration Status]]="Completed",AB4="NPI Match"),"Ready","Not Ready"),"Not Applicable") -> Not Ready | AI4: =IF(tblEnrollment[[#This Row],[Blocker Reason]] ="No Blocker","No","Yes") -> Yes | AK4: Blank Payer Names | AL4: =COUNTBLANK(tblEnrollment[Payer Name]) -> 0
A5: ENR-0004 | B5: Maple Leaf Urgent Care | C5: Dr. Emily Gray | D5: IND-NPI-1004 | E5: GRP-NPI-9023 | F5: GRP-NPI-9023 | G5: GRP-NPI-9023 | H5: SYN-TIN-011 | I5: United Healthcare | J5: UHC001 | K5: Commercial | L5: NA | M5: ERA | N5: Completed | O5: Not Required | P5: Approved | Q5: Yes | R5: Completed | S5: 46154 | T5: 46169 | U5: Ready | V5: No blocker | W5: rc48215 | X5: 46177 | Y5: Record is ready for expected transaction flow. | Z5: =IF(tblEnrollment[[#This Row],[Approved Date]]="",DATE(2026,6,3)-tblEnrollment[[#This Row],[Submitted Date]],tblEnrollment[[#This Row],[Approved Date]]-tblEnrollment[[#This Row],[Submitted Date]]) -> 15 | AA5: =IF(tblEnrollment[[#This Row],[Current Status]] ="Ready","Completed",IF(Z5>21,"SLA Breached","Within SLA")) -> Completed | AB5: =IF(tblEnrollment[[#This Row],[Credentialed NPI]] =tblEnrollment[[#This Row],[Enrolled NPI]],"NPI Match","NPI Mismatch") -> NPI Match | AC5: =IF(OR(tblEnrollment[[#This Row],[Blocker Reason]] ="Individual NPI used instead of Group NPI",tblEnrollment[[#This Row],[Blocker Reason]] ="Credentialed NPI mismatch",tblEnrollment[[#This Row],[Blocker Reason]] ="Incorrect PTAN/Provider number"),"Yes","No") -> No | AD5: =IF(OR(tblEnrollment[[#This Row],[Blocker Reason]] ="Wrong Payer ID",tblEnrollment[[#This Row],[Blocker Reason]] ="Old Payer ID used"),"Yes","No") -> No | AE5: =IF(OR(tblEnrollment[[#This Row],[Clearinghouse Portal Updated]]="No",tblEnrollment[[#This Row],[Blocker Reason]] ="Clearinghouse portal not updated"),"Yes","No") -> No | AF5: =IF(OR(tblEnrollment[[#This Row],[Blocker Reason]] ="Medicaid additional enrollment missing",tblEnrollment[Blocker Reason]="Medicaid requires additional enrollment after credentialing.",tblEnrollment[[#This Row],[Blocker Reason]] ="Incorrect PTAN/Provider number",tblEnrollment[[#This Row],[Blocker Reason]] ="Medicare additional enrollment missing"),"Yes","No") -> No | AG5: =IF(OR(tblEnrollment[[#This Row],[Enrollment Type]]="Claims",tblEnrollment[[#This Row],[Enrollment Type]]="Claims and ERA"),IF(AND(tblEnrollment[[#This Row],[Credentialing Status]]="Completed",tblEnrollment[[#This Row],[Claims Enrollment Status]]="Approved",tblEnrollment[[#This Row],[Clearinghouse Configuration Status]]="Completed",AB5="NPI Match"),"Ready","Not Ready"),"Not Applicable") -> Not Applicable | AH5: =IF(OR(tblEnrollment[[#This Row],[Enrollment Type]]="ERA",tblEnrollment[[#This Row],[Enrollment Type]]="Claims and ERA"),IF(AND(tblEnrollment[[#This Row],[Credentialing Status]]="Completed",tblEnrollment[[#This Row],[ERA Enrollment Status]]="Approved",tblEnrollment[[#This Row],[Clearinghouse Configuration Status]]="Completed",AB5="NPI Match"),"Ready","Not Ready"),"Not Applicable") -> Ready | AI5: =IF(tblEnrollment[[#This Row],[Blocker Reason]] ="No Blocker","No","Yes") -> No | AK5: Blank Practice Name | AL5: =COUNTBLANK(tblEnrollment[[#Headers],[#Data],[Provider Name]]) -> 0
A6: ENR-0005 | B6: Sunrise Family Medicine | C6: Dr. Grace Das | D6: IND-NPI-1005 | E6: GRP-NPI-9041 | F6: GRP-NPI-9041 | G6: GRP-NPI-9041 | H6: SYN-TIN-006 | I6: United Healthcare | J6: UHC001 | K6: Commercial | L6: NA | M6: Claims and ERA | N6: Completed | O6: Approved | P6: Pending | Q6: No | R6: Pending | S6: 46086 | U6: Pending | V6: Clearinghouse portal not updated | W6: nt92346 | X6: 46187 | Y6: Clearinghouse route or portal setup needs update before go-live. | Z6: =IF(tblEnrollment[[#This Row],[Approved Date]]="",DATE(2026,6,3)-tblEnrollment[[#This Row],[Submitted Date]],tblEnrollment[[#This Row],[Approved Date]]-tblEnrollment[[#This Row],[Submitted Date]]) -> 90 | AA6: =IF(tblEnrollment[[#This Row],[Current Status]] ="Ready","Completed",IF(Z6>21,"SLA Breached","Within SLA")) -> SLA Breached | AB6: =IF(tblEnrollment[[#This Row],[Credentialed NPI]] =tblEnrollment[[#This Row],[Enrolled NPI]],"NPI Match","NPI Mismatch") -> NPI Match | AC6: =IF(OR(tblEnrollment[[#This Row],[Blocker Reason]] ="Individual NPI used instead of Group NPI",tblEnrollment[[#This Row],[Blocker Reason]] ="Credentialed NPI mismatch",tblEnrollment[[#This Row],[Blocker Reason]] ="Incorrect PTAN/Provider number"),"Yes","No") -> No | AD6: =IF(OR(tblEnrollment[[#This Row],[Blocker Reason]] ="Wrong Payer ID",tblEnrollment[[#This Row],[Blocker Reason]] ="Old Payer ID used"),"Yes","No") -> No | AE6: =IF(OR(tblEnrollment[[#This Row],[Clearinghouse Portal Updated]]="No",tblEnrollment[[#This Row],[Blocker Reason]] ="Clearinghouse portal not updated"),"Yes","No") -> Yes | AF6: =IF(OR(tblEnrollment[[#This Row],[Blocker Reason]] ="Medicaid additional enrollment missing",tblEnrollment[Blocker Reason]="Medicaid requires additional enrollment after credentialing.",tblEnrollment[[#This Row],[Blocker Reason]] ="Incorrect PTAN/Provider number",tblEnrollment[[#This Row],[Blocker Reason]] ="Medicare additional enrollment missing"),"Yes","No") -> No | AG6: =IF(OR(tblEnrollment[[#This Row],[Enrollment Type]]="Claims",tblEnrollment[[#This Row],[Enrollment Type]]="Claims and ERA"),IF(AND(tblEnrollment[[#This Row],[Credentialing Status]]="Completed",tblEnrollment[[#This Row],[Claims Enrollment Status]]="Approved",tblEnrollment[[#This Row],[Clearinghouse Configuration Status]]="Completed",AB6="NPI Match"),"Ready","Not Ready"),"Not Applicable") -> Not Ready | AH6: =IF(OR(tblEnrollment[[#This Row],[Enrollment Type]]="ERA",tblEnrollment[[#This Row],[Enrollment Type]]="Claims and ERA"),IF(AND(tblEnrollment[[#This Row],[Credentialing Status]]="Completed",tblEnrollment[[#This Row],[ERA Enrollment Status]]="Approved",tblEnrollment[[#This Row],[Clearinghouse Configuration Status]]="Completed",AB6="NPI Match"),"Ready","Not Ready"),"Not Applicable") -> Not Ready | AI6: =IF(tblEnrollment[[#This Row],[Blocker Reason]] ="No Blocker","No","Yes") -> Yes | AK6: Blank Submitted Dates | AL6: =COUNTBLANK(tblEnrollment[Submitted Date]) -> 0
A7: ENR-0006 | B7: Coral Springs Primary Care | C7: Dr. Lily Singh | D7: IND-NPI-1006 | E7: GRP-NPI-9019 | F7: GRP-NPI-9019 | G7: GRP-NPI-9019 | H7: SYN-TIN-047 | I7: Medicare | J7: MED001 | K7: Government | L7: PTAN-0006 | M7: Claims and ERA | N7: Completed | O7: Pending | P7: Pending | Q7: Yes | R7: In Progress | S7: 46134 | U7: Pending | V7: Missing payer approval | W7: rc48215 | X7: 46180 | Y7: Waiting on payer approval or payer response. | Z7: =IF(tblEnrollment[[#This Row],[Approved Date]]="",DATE(2026,6,3)-tblEnrollment[[#This Row],[Submitted Date]],tblEnrollment[[#This Row],[Approved Date]]-tblEnrollment[[#This Row],[Submitted Date]]) -> 42 | AA7: =IF(tblEnrollment[[#This Row],[Current Status]] ="Ready","Completed",IF(Z7>21,"SLA Breached","Within SLA")) -> SLA Breached | AB7: =IF(tblEnrollment[[#This Row],[Credentialed NPI]] =tblEnrollment[[#This Row],[Enrolled NPI]],"NPI Match","NPI Mismatch") -> NPI Match | AC7: =IF(OR(tblEnrollment[[#This Row],[Blocker Reason]] ="Individual NPI used instead of Group NPI",tblEnrollment[[#This Row],[Blocker Reason]] ="Credentialed NPI mismatch",tblEnrollment[[#This Row],[Blocker Reason]] ="Incorrect PTAN/Provider number"),"Yes","No") -> No | AD7: =IF(OR(tblEnrollment[[#This Row],[Blocker Reason]] ="Wrong Payer ID",tblEnrollment[[#This Row],[Blocker Reason]] ="Old Payer ID used"),"Yes","No") -> No | AE7: =IF(OR(tblEnrollment[[#This Row],[Clearinghouse Portal Updated]]="No",tblEnrollment[[#This Row],[Blocker Reason]] ="Clearinghouse portal not updated"),"Yes","No") -> No | AF7: =IF(OR(tblEnrollment[[#This Row],[Blocker Reason]] ="Medicaid additional enrollment missing",tblEnrollment[Blocker Reason]="Medicaid requires additional enrollment after credentialing.",tblEnrollment[[#This Row],[Blocker Reason]] ="Incorrect PTAN/Provider number",tblEnrollment[[#This Row],[Blocker Reason]] ="Medicare additional enrollment missing"),"Yes","No") -> No | AG7: =IF(OR(tblEnrollment[[#This Row],[Enrollment Type]]="Claims",tblEnrollment[[#This Row],[Enrollment Type]]="Claims and ERA"),IF(AND(tblEnrollment[[#This Row],[Credentialing Status]]="Completed",tblEnrollment[[#This Row],[Claims Enrollment Status]]="Approved",tblEnrollment[[#This Row],[Clearinghouse Configuration Status]]="Completed",AB7="NPI Match"),"Ready","Not Ready"),"Not Applicable") -> Not Ready | AH7: =IF(OR(tblEnrollment[[#This Row],[Enrollment Type]]="ERA",tblEnrollment[[#This Row],[Enrollment Type]]="Claims and ERA"),IF(AND(tblEnrollment[[#This Row],[Credentialing Status]]="Completed",tblEnrollment[[#This Row],[ERA Enrollment Status]]="Approved",tblEnrollment[[#This Row],[Clearinghouse Configuration Status]]="Completed",AB7="NPI Match"),"Ready","Not Ready"),"Not Applicable") -> Not Ready | AI7: =IF(tblEnrollment[[#This Row],[Blocker Reason]] ="No Blocker","No","Yes") -> Yes | AK7: Invalid Current Status | AL7: =COUNTBLANK(tblEnrollment[Current Status]) -> 0
A8: ENR-0007 | B8: BrightCare Cardiology | C8: Dr. Elena Gray | D8: IND-NPI-1007 | E8: GRP-NPI-9014 | F8: GRP-NPI-9014 | G8: GRP-NPI-9014 | H8: SYN-TIN-032 | I8: Cigna | J8: CIG001 | K8: Commercial | L8: NA | M8: ERA | N8: Completed | O8: Not Required | P8: Pending | Q8: Yes | R8: In Progress | S8: 46055 | U8: Pending | V8: ERA setup not completed | W8: nt00234 | X8: 46185 | Y8: ERA enrollment or routing is not fully completed. | Z8: =IF(tblEnrollment[[#This Row],[Approved Date]]="",DATE(2026,6,3)-tblEnrollment[[#This Row],[Submitted Date]],tblEnrollment[[#This Row],[Approved Date]]-tblEnrollment[[#This Row],[Submitted Date]]) -> 121 | AA8: =IF(tblEnrollment[[#This Row],[Current Status]] ="Ready","Completed",IF(Z8>21,"SLA Breached","Within SLA")) -> SLA Breached | AB8: =IF(tblEnrollment[[#This Row],[Credentialed NPI]] =tblEnrollment[[#This Row],[Enrolled NPI]],"NPI Match","NPI Mismatch") -> NPI Match | AC8: =IF(OR(tblEnrollment[[#This Row],[Blocker Reason]] ="Individual NPI used instead of Group NPI",tblEnrollment[[#This Row],[Blocker Reason]] ="Credentialed NPI mismatch",tblEnrollment[[#This Row],[Blocker Reason]] ="Incorrect PTAN/Provider number"),"Yes","No") -> No | AD8: =IF(OR(tblEnrollment[[#This Row],[Blocker Reason]] ="Wrong Payer ID",tblEnrollment[[#This Row],[Blocker Reason]] ="Old Payer ID used"),"Yes","No") -> No | AE8: =IF(OR(tblEnrollment[[#This Row],[Clearinghouse Portal Updated]]="No",tblEnrollment[[#This Row],[Blocker Reason]] ="Clearinghouse portal not updated"),"Yes","No") -> No | AF8: =IF(OR(tblEnrollment[[#This Row],[Blocker Reason]] ="Medicaid additional enrollment missing",tblEnrollment[Blocker Reason]="Medicaid requires additional enrollment after credentialing.",tblEnrollment[[#This Row],[Blocker Reason]] ="Incorrect PTAN/Provider number",tblEnrollment[[#This Row],[Blocker Reason]] ="Medicare additional enrollment missing"),"Yes","No") -> No | AG8: =IF(OR(tblEnrollment[[#This Row],[Enrollment Type]]="Claims",tblEnrollment[[#This Row],[Enrollment Type]]="Claims and ERA"),IF(AND(tblEnrollment[[#This Row],[Credentialing Status]]="Completed",tblEnrollment[[#This Row],[Claims Enrollment Status]]="Approved",tblEnrollment[[#This Row],[Clearinghouse Configuration Status]]="Completed",AB8="NPI Match"),"Ready","Not Ready"),"Not Applicable") -> Not Applicable | AH8: =IF(OR(tblEnrollment[[#This Row],[Enrollment Type]]="ERA",tblEnrollment[[#This Row],[Enrollment Type]]="Claims and ERA"),IF(AND(tblEnrollment[[#This Row],[Credentialing Status]]="Completed",tblEnrollment[[#This Row],[ERA Enrollment Status]]="Approved",tblEnrollment[[#This Row],[Clearinghouse Configuration Status]]="Completed",AB8="NPI Match"),"Ready","Not Ready"),"Not Applicable") -> Not Ready | AI8: =IF(tblEnrollment[[#This Row],[Blocker Reason]] ="No Blocker","No","Yes") -> Yes | AK8: Npi Mismatch Record | AL8: =COUNTIF(tblEnrollment[NPI Match Status],"NPI Mismatch") -> 59
A9: ENR-0008 | B9: BrightCare Cardiology | C9: Dr. Aria Kapoor | D9: IND-NPI-1008 | E9: GRP-NPI-9018 | F9: GRP-NPI-9018 | G9: GRP-NPI-9018 | H9: SYN-TIN-005 | I9: Cigna | J9: CIG001 | K9: Commercial | L9: NA | M9: Claims and ERA | N9: Completed | O9: Approved | P9: Approved | Q9: Yes | R9: Completed | S9: 46120 | T9: 46140 | U9: Ready | V9: No blocker | W9: nt00234 | X9: 46176 | Y9: Record is ready for expected transaction flow. | Z9: =IF(tblEnrollment[[#This Row],[Approved Date]]="",DATE(2026,6,3)-tblEnrollment[[#This Row],[Submitted Date]],tblEnrollment[[#This Row],[Approved Date]]-tblEnrollment[[#This Row],[Submitted Date]]) -> 20 | AA9: =IF(tblEnrollment[[#This Row],[Current Status]] ="Ready","Completed",IF(Z9>21,"SLA Breached","Within SLA")) -> Completed | AB9: =IF(tblEnrollment[[#This Row],[Credentialed NPI]] =tblEnrollment[[#This Row],[Enrolled NPI]],"NPI Match","NPI Mismatch") -> NPI Match | AC9: =IF(OR(tblEnrollment[[#This Row],[Blocker Reason]] ="Individual NPI used instead of Group NPI",tblEnrollment[[#This Row],[Blocker Reason]] ="Credentialed NPI mismatch",tblEnrollment[[#This Row],[Blocker Reason]] ="Incorrect PTAN/Provider number"),"Yes","No") -> No | AD9: =IF(OR(tblEnrollment[[#This Row],[Blocker Reason]] ="Wrong Payer ID",tblEnrollment[[#This Row],[Blocker Reason]] ="Old Payer ID used"),"Yes","No") -> No | AE9: =IF(OR(tblEnrollment[[#This Row],[Clearinghouse Portal Updated]]="No",tblEnrollment[[#This Row],[Blocker Reason]] ="Clearinghouse portal not updated"),"Yes","No") -> No | AF9: =IF(OR(tblEnrollment[[#This Row],[Blocker Reason]] ="Medicaid additional enrollment missing",tblEnrollment[Blocker Reason]="Medicaid requires additional enrollment after credentialing.",tblEnrollment[[#This Row],[Blocker Reason]] ="Incorrect PTAN/Provider number",tblEnrollment[[#This Row],[Blocker Reason]] ="Medicare additional enrollment missing"),"Yes","No") -> No | AG9: =IF(OR(tblEnrollment[[#This Row],[Enrollment Type]]="Claims",tblEnrollment[[#This Row],[Enrollment Type]]="Claims and ERA"),IF(AND(tblEnrollment[[#This Row],[Credentialing Status]]="Completed",tblEnrollment[[#This Row],[Claims Enrollment Status]]="Approved",tblEnrollment[[#This Row],[Clearinghouse Configuration Status]]="Completed",AB9="NPI Match"),"Ready","Not Ready"),"Not Applicable") -> Ready | AH9: =IF(OR(tblEnrollment[[#This Row],[Enrollment Type]]="ERA",tblEnrollment[[#This Row],[Enrollment Type]]="Claims and ERA"),IF(AND(tblEnrollment[[#This Row],[Credentialing Status]]="Completed",tblEnrollment[[#This Row],[ERA Enrollment Status]]="Approved",tblEnrollment[[#This Row],[Clearinghouse Configuration Status]]="Completed",AB9="NPI Match"),"Ready","Not Ready"),"Not Applicable") -> Ready | AI9: =IF(tblEnrollment[[#This Row],[Blocker Reason]] ="No Blocker","No","Yes") -> No | AK9: SLA Breach count | AL9: =COUNTIF(tblEnrollment[SLA Status],"=SLA Breached") -> 158
A10: ENR-0009 | B10: Liberty Primary Care | C10: Dr. Kevin Kapoor | D10: IND-NPI-1009 | E10: GRP-NPI-9018 | F10: GRP-NPI-9018 | G10: GRP-NPI-9018 | H10: SYN-TIN-051 | I10: Medicare | J10: MED001 | K10: Government | L10: PTAN-0009 | M10: Claims | N10: Completed | O10: Rejected | P10: Not Required | Q10: Yes | R10: In Progress | S10: 46117 | U10: Pending | V10: Medicare additional enrollment missing | W10: rc48215 | X10: 46179 | Y10: Medicare requires additional enrollment after credentialing. | Z10: =IF(tblEnrollment[[#This Row],[Approved Date]]="",DATE(2026,6,3)-tblEnrollment[[#This Row],[Submitted Date]],tblEnrollment[[#This Row],[Approved Date]]-tblEnrollment[[#This Row],[Submitted Date]]) -> 59 | AA10: =IF(tblEnrollment[[#This Row],[Current Status]] ="Ready","Completed",IF(Z10>21,"SLA Breached","Within SLA")) -> SLA Breached | AB10: =IF(tblEnrollment[[#This Row],[Credentialed NPI]] =tblEnrollment[[#This Row],[Enrolled NPI]],"NPI Match","NPI Mismatch") -> NPI Match | AC10: =IF(OR(tblEnrollment[[#This Row],[Blocker Reason]] ="Individual NPI used instead of Group NPI",tblEnrollment[[#This Row],[Blocker Reason]] ="Credentialed NPI mismatch",tblEnrollment[[#This Row],[Blocker Reason]] ="Incorrect PTAN/Provider number"),"Yes","No") -> No | AD10: =IF(OR(tblEnrollment[[#This Row],[Blocker Reason]] ="Wrong Payer ID",tblEnrollment[[#This Row],[Blocker Reason]] ="Old Payer ID used"),"Yes","No") -> No | AE10: =IF(OR(tblEnrollment[[#This Row],[Clearinghouse Portal Updated]]="No",tblEnrollment[[#This Row],[Blocker Reason]] ="Clearinghouse portal not updated"),"Yes","No") -> No | AF10: =IF(OR(tblEnrollment[[#This Row],[Blocker Reason]] ="Medicaid additional enrollment missing",tblEnrollment[Blocker Reason]="Medicaid requires additional enrollment after credentialing.",tblEnrollment[[#This Row],[Blocker Reason]] ="Incorrect PTAN/Provider number",tblEnrollment[[#This Row],[Blocker Reason]] ="Medicare additional enrollment missing"),"Yes","No") -> Yes | AG10: =IF(OR(tblEnrollment[[#This Row],[Enrollment Type]]="Claims",tblEnrollment[[#This Row],[Enrollment Type]]="Claims and ERA"),IF(AND(tblEnrollment[[#This Row],[Credentialing Status]]="Completed",tblEnrollment[[#This Row],[Claims Enrollment Status]]="Approved",tblEnrollment[[#This Row],[Clearinghouse Configuration Status]]="Completed",AB10="NPI Match"),"Ready","Not Ready"),"Not Applicable") -> Not Ready | AH10: =IF(OR(tblEnrollment[[#This Row],[Enrollment Type]]="ERA",tblEnrollment[[#This Row],[Enrollment Type]]="Claims and ERA"),IF(AND(tblEnrollment[[#This Row],[Credentialing Status]]="Completed",tblEnrollment[[#This Row],[ERA Enrollment Status]]="Approved",tblEnrollment[[#This Row],[Clearinghouse Configuration Status]]="Completed",AB10="NPI Match"),"Ready","Not Ready"),"Not Applicable") -> Not Applicable | AI10: =IF(tblEnrollment[[#This Row],[Blocker Reason]] ="No Blocker","No","Yes") -> Yes | AK10: claims ready count | AL10: =COUNTIF(tblEnrollment[Claims Ready Flag],"=Ready") -> 48
A11: ENR-0010 | B11: Stonebridge Family Medicine | C11: Dr. Aria Wilson | D11: IND-NPI-1010 | E11: GRP-NPI-9017 | F11: GRP-NPI-9017 | G11: GRP-NPI-9017 | H11: SYN-TIN-047 | I11: Medicaid | J11: MCD002 | K11: Government | L11: PTAN-WRONG | M11: Claims | N11: Completed | O11: Rejected | P11: Not Required | Q11: Yes | R11: Issue Found | S11: 46146 | U11: Blocked | V11: Incorrect PTAN/provider number | W11: rc48215 | X11: 46185 | Y11: PTAN or government payer provider number needs correction. | Z11: =IF(tblEnrollment[[#This Row],[Approved Date]]="",DATE(2026,6,3)-tblEnrollment[[#This Row],[Submitted Date]],tblEnrollment[[#This Row],[Approved Date]]-tblEnrollment[[#This Row],[Submitted Date]]) -> 30 | AA11: =IF(tblEnrollment[[#This Row],[Current Status]] ="Ready","Completed",IF(Z11>21,"SLA Breached","Within SLA")) -> SLA Breached | AB11: =IF(tblEnrollment[[#This Row],[Credentialed NPI]] =tblEnrollment[[#This Row],[Enrolled NPI]],"NPI Match","NPI Mismatch") -> NPI Match | AC11: =IF(OR(tblEnrollment[[#This Row],[Blocker Reason]] ="Individual NPI used instead of Group NPI",tblEnrollment[[#This Row],[Blocker Reason]] ="Credentialed NPI mismatch",tblEnrollment[[#This Row],[Blocker Reason]] ="Incorrect PTAN/Provider number"),"Yes","No") -> Yes | AD11: =IF(OR(tblEnrollment[[#This Row],[Blocker Reason]] ="Wrong Payer ID",tblEnrollment[[#This Row],[Blocker Reason]] ="Old Payer ID used"),"Yes","No") -> No | AE11: =IF(OR(tblEnrollment[[#This Row],[Clearinghouse Portal Updated]]="No",tblEnrollment[[#This Row],[Blocker Reason]] ="Clearinghouse portal not updated"),"Yes","No") -> No | AF11: =IF(OR(tblEnrollment[[#This Row],[Blocker Reason]] ="Medicaid additional enrollment missing",tblEnrollment[Blocker Reason]="Medicaid requires additional enrollment after credentialing.",tblEnrollment[[#This Row],[Blocker Reason]] ="Incorrect PTAN/Provider number",tblEnrollment[[#This Row],[Blocker Reason]] ="Medicare additional enrollment missing"),"Yes","No") -> Yes | AG11: =IF(OR(tblEnrollment[[#This Row],[Enrollment Type]]="Claims",tblEnrollment[[#This Row],[Enrollment Type]]="Claims and ERA"),IF(AND(tblEnrollment[[#This Row],[Credentialing Status]]="Completed",tblEnrollment[[#This Row],[Claims Enrollment Status]]="Approved",tblEnrollment[[#This Row],[Clearinghouse Configuration Status]]="Completed",AB11="NPI Match"),"Ready","Not Ready"),"Not Applicable") -> Not Ready | AH11: =IF(OR(tblEnrollment[[#This Row],[Enrollment Type]]="ERA",tblEnrollment[[#This Row],[Enrollment Type]]="Claims and ERA"),IF(AND(tblEnrollment[[#This Row],[Credentialing Status]]="Completed",tblEnrollment[[#This Row],[ERA Enrollment Status]]="Approved",tblEnrollment[[#This Row],[Clearinghouse Configuration Status]]="Completed",AB11="NPI Match"),"Ready","Not Ready"),"Not Applicable") -> Not Applicable | AI11: =IF(tblEnrollment[[#This Row],[Blocker Reason]] ="No Blocker","No","Yes") -> Yes | AK11: ERA ready count | AL11: =COUNTIF(tblEnrollment[ERA Ready Flag],"=Ready") -> 38
A12: ENR-0011 | B12: Oak Street Primary Care | C12: Dr. Sara Scott | D12: IND-NPI-1011 | E12: GRP-NPI-9032 | F12: GRP-NPI-9032 | G12: GRP-NPI-9032 | H12: SYN-TIN-055 | I12: Medicare | J12: MED001 | K12: Government | L12: PTAN-0011 | M12: Claims and ERA | N12: Completed | O12: Pending | P12: Pending | Q12: Yes | R12: In Progress | S12: 46076 | U12: Pending | V12: Missing payer approval | W12: nt00234 | X12: 46186 | Y12: Waiting on payer approval or payer response. | Z12: =IF(tblEnrollment[[#This Row],[Approved Date]]="",DATE(2026,6,3)-tblEnrollment[[#This Row],[Submitted Date]],tblEnrollment[[#This Row],[Approved Date]]-tblEnrollment[[#This Row],[Submitted Date]]) -> 100 | AA12: =IF(tblEnrollment[[#This Row],[Current Status]] ="Ready","Completed",IF(Z12>21,"SLA Breached","Within SLA")) -> SLA Breached | AB12: =IF(tblEnrollment[[#This Row],[Credentialed NPI]] =tblEnrollment[[#This Row],[Enrolled NPI]],"NPI Match","NPI Mismatch") -> NPI Match | AC12: =IF(OR(tblEnrollment[[#This Row],[Blocker Reason]] ="Individual NPI used instead of Group NPI",tblEnrollment[[#This Row],[Blocker Reason]] ="Credentialed NPI mismatch",tblEnrollment[[#This Row],[Blocker Reason]] ="Incorrect PTAN/Provider number"),"Yes","No") -> No | AD12: =IF(OR(tblEnrollment[[#This Row],[Blocker Reason]] ="Wrong Payer ID",tblEnrollment[[#This Row],[Blocker Reason]] ="Old Payer ID used"),"Yes","No") -> No | AE12: =IF(OR(tblEnrollment[[#This Row],[Clearinghouse Portal Updated]]="No",tblEnrollment[[#This Row],[Blocker Reason]] ="Clearinghouse portal not updated"),"Yes","No") -> No | AF12: =IF(OR(tblEnrollment[[#This Row],[Blocker Reason]] ="Medicaid additional enrollment missing",tblEnrollment[Blocker Reason]="Medicaid requires additional enrollment after credentialing.",tblEnrollment[[#This Row],[Blocker Reason]] ="Incorrect PTAN/Provider number",tblEnrollment[[#This Row],[Blocker Reason]] ="Medicare additional enrollment missing"),"Yes","No") -> No | AG12: =IF(OR(tblEnrollment[[#This Row],[Enrollment Type]]="Claims",tblEnrollment[[#This Row],[Enrollment Type]]="Claims and ERA"),IF(AND(tblEnrollment[[#This Row],[Credentialing Status]]="Completed",tblEnrollment[[#This Row],[Claims Enrollment Status]]="Approved",tblEnrollment[[#This Row],[Clearinghouse Configuration Status]]="Completed",AB12="NPI Match"),"Ready","Not Ready"),"Not Applicable") -> Not Ready | AH12: =IF(OR(tblEnrollment[[#This Row],[Enrollment Type]]="ERA",tblEnrollment[[#This Row],[Enrollment Type]]="Claims and ERA"),IF(AND(tblEnrollment[[#This Row],[Credentialing Status]]="Completed",tblEnrollment[[#This Row],[ERA Enrollment Status]]="Approved",tblEnrollment[[#This Row],[Clearinghouse Configuration Status]]="Completed",AB12="NPI Match"),"Ready","Not Ready"),"Not Applicable") -> Not Ready | AI12: =IF(tblEnrollment[[#This Row],[Blocker Reason]] ="No Blocker","No","Yes") -> Yes
A13: ENR-0012 | B13: Parkside Oncology | C13: Dr. Mark Kapoor | D13: IND-NPI-1012 | E13: GRP-NPI-9025 | F13: GRP-NPI-9025 | G13: GRP-NPI-9136 | H13: SYN-TIN-035 | I13: United Healthcare | J13: UHC001 | K13: Commercial | L13: NA | M13: Claims and ERA | N13: Completed | O13: Rejected | P13: Rejected | Q13: Yes | R13: Issue Found | S13: 46039 | U13: Blocked | V13: Credentialed NPI mismatch | W13: nt92346 | X13: 46186 | Y13: Enrolled NPI does not match the payer-credentialed NPI. | Z13: =IF(tblEnrollment[[#This Row],[Approved Date]]="",DATE(2026,6,3)-tblEnrollment[[#This Row],[Submitted Date]],tblEnrollment[[#This Row],[Approved Date]]-tblEnrollment[[#This Row],[Submitted Date]]) -> 137 | AA13: =IF(tblEnrollment[[#This Row],[Current Status]] ="Ready","Completed",IF(Z13>21,"SLA Breached","Within SLA")) -> SLA Breached | AB13: =IF(tblEnrollment[[#This Row],[Credentialed NPI]] =tblEnrollment[[#This Row],[Enrolled NPI]],"NPI Match","NPI Mismatch") -> NPI Mismatch | AC13: =IF(OR(tblEnrollment[[#This Row],[Blocker Reason]] ="Individual NPI used instead of Group NPI",tblEnrollment[[#This Row],[Blocker Reason]] ="Credentialed NPI mismatch",tblEnrollment[[#This Row],[Blocker Reason]] ="Incorrect PTAN/Provider number"),"Yes","No") -> Yes | AD13: =IF(OR(tblEnrollment[[#This Row],[Blocker Reason]] ="Wrong Payer ID",tblEnrollment[[#This Row],[Blocker Reason]] ="Old Payer ID used"),"Yes","No") -> No | AE13: =IF(OR(tblEnrollment[[#This Row],[Clearinghouse Portal Updated]]="No",tblEnrollment[[#This Row],[Blocker Reason]] ="Clearinghouse portal not updated"),"Yes","No") -> No | AF13: =IF(OR(tblEnrollment[[#This Row],[Blocker Reason]] ="Medicaid additional enrollment missing",tblEnrollment[Blocker Reason]="Medicaid requires additional enrollment after credentialing.",tblEnrollment[[#This Row],[Blocker Reason]] ="Incorrect PTAN/Provider number",tblEnrollment[[#This Row],[Blocker Reason]] ="Medicare additional enrollment missing"),"Yes","No") -> No | AG13: =IF(OR(tblEnrollment[[#This Row],[Enrollment Type]]="Claims",tblEnrollment[[#This Row],[Enrollment Type]]="Claims and ERA"),IF(AND(tblEnrollment[[#This Row],[Credentialing Status]]="Completed",tblEnrollment[[#This Row],[Claims Enrollment Status]]="Approved",tblEnrollment[[#This Row],[Clearinghouse Configuration Status]]="Completed",AB13="NPI Match"),"Ready","Not Ready"),"Not Applicable") -> Not Ready | AH13: =IF(OR(tblEnrollment[[#This Row],[Enrollment Type]]="ERA",tblEnrollment[[#This Row],[Enrollment Type]]="Claims and ERA"),IF(AND(tblEnrollment[[#This Row],[Credentialing Status]]="Completed",tblEnrollment[[#This Row],[ERA Enrollment Status]]="Approved",tblEnrollment[[#This Row],[Clearinghouse Configuration Status]]="Completed",AB13="NPI Match"),"Ready","Not Ready"),"Not Applicable") -> Not Ready | AI13: =IF(tblEnrollment[[#This Row],[Blocker Reason]] ="No Blocker","No","Yes") -> Yes
A14: ENR-0013 | B14: Clearwater Pulmonary | C14: Dr. Meera Shah | D14: IND-NPI-1013 | E14: GRP-NPI-9019 | F14: GRP-NPI-9019 | G14: GRP-NPI-9019 | H14: SYN-TIN-014 | I14: Aetna | J14: AET001 | K14: Commercial | L14: NA | M14: Claims | N14: Completed | O14: Approved | P14: Not Required | Q14: Yes | R14: Completed | S14: 46104 | T14: 46119 | U14: Ready | V14: No blocker | W14: ew53009 | X14: 46178 | Y14: Record is ready for expected transaction flow. | Z14: =IF(tblEnrollment[[#This Row],[Approved Date]]="",DATE(2026,6,3)-tblEnrollment[[#This Row],[Submitted Date]],tblEnrollment[[#This Row],[Approved Date]]-tblEnrollment[[#This Row],[Submitted Date]]) -> 15 | AA14: =IF(tblEnrollment[[#This Row],[Current Status]] ="Ready","Completed",IF(Z14>21,"SLA Breached","Within SLA")) -> Completed | AB14: =IF(tblEnrollment[[#This Row],[Credentialed NPI]] =tblEnrollment[[#This Row],[Enrolled NPI]],"NPI Match","NPI Mismatch") -> NPI Match | AC14: =IF(OR(tblEnrollment[[#This Row],[Blocker Reason]] ="Individual NPI used instead of Group NPI",tblEnrollment[[#This Row],[Blocker Reason]] ="Credentialed NPI mismatch",tblEnrollment[[#This Row],[Blocker Reason]] ="Incorrect PTAN/Provider number"),"Yes","No") -> No | AD14: =IF(OR(tblEnrollment[[#This Row],[Blocker Reason]] ="Wrong Payer ID",tblEnrollment[[#This Row],[Blocker Reason]] ="Old Payer ID used"),"Yes","No") -> No | AE14: =IF(OR(tblEnrollment[[#This Row],[Clearinghouse Portal Updated]]="No",tblEnrollment[[#This Row],[Blocker Reason]] ="Clearinghouse portal not updated"),"Yes","No") -> No | AF14: =IF(OR(tblEnrollment[[#This Row],[Blocker Reason]] ="Medicaid additional enrollment missing",tblEnrollment[Blocker Reason]="Medicaid requires additional enrollment after credentialing.",tblEnrollment[[#This Row],[Blocker Reason]] ="Incorrect PTAN/Provider number",tblEnrollment[[#This Row],[Blocker Reason]] ="Medicare additional enrollment missing"),"Yes","No") -> No | AG14: =IF(OR(tblEnrollment[[#This Row],[Enrollment Type]]="Claims",tblEnrollment[[#This Row],[Enrollment Type]]="Claims and ERA"),IF(AND(tblEnrollment[[#This Row],[Credentialing Status]]="Completed",tblEnrollment[[#This Row],[Claims Enrollment Status]]="Approved",tblEnrollment[[#This Row],[Clearinghouse Configuration Status]]="Completed",AB14="NPI Match"),"Ready","Not Ready"),"Not Applicable") -> Ready | AH14: =IF(OR(tblEnrollment[[#This Row],[Enrollment Type]]="ERA",tblEnrollment[[#This Row],[Enrollment Type]]="Claims and ERA"),IF(AND(tblEnrollment[[#This Row],[Credentialing Status]]="Completed",tblEnrollment[[#This Row],[ERA Enrollment Status]]="Approved",tblEnrollment[[#This Row],[Clearinghouse Configuration Status]]="Completed",AB14="NPI Match"),"Ready","Not Ready"),"Not Applicable") -> Not Applicable | AI14: =IF(tblEnrollment[[#This Row],[Blocker Reason]] ="No Blocker","No","Yes") -> No
