Workbook

Sheet raw_enrollment_data
A1: Record_ID | B1: Practice Name | C1: Provider Name | D1: Individual NPI | E1: Group NPI | F1: Credentialed NPI | G1: Enrolled NPI | H1: Tax ID | I1: Payer Name | J1: Payer ID | K1: Payer Type | L1: PTAN/Provider number | M1: Enrollment Type | N1: Credentialing status | O1: Claims_Enrollment_Status | P1: ERA Enrollment Status | Q1: EEP updated? | R1: EEP Status | S1: Submitted Date | T1: Approved date | U1: Current Status | V1: Blocked reason | W1: Assigned Owner | X1: Follow-up Date | Y1: Notes
A2: ENR-001 | B2: River Valley Family Care | C2: Dr. JIM Fitz | D2: IND-NPI-1001 | E2: GRP-NPI-9001 | F2: GRP-NPI-9001 | G2: GRP-NPI-9001 | H2: SYN-TIN-001 | I2: Medicare | J2: MED01 | K2: Government | L2: PTAN-001 | M2: Claims and ERA | N2: Completed | O2: Approved | P2: Approved | Q2: Yes | R2: Completed | S2: 46113 | T2: 46130 | U2: Ready | V2: No Blocker | W2: Nt92346 | X2: 46176 | Y2: Ready for claims and ERA
A3: ENR-002 | B3: River Valley Family Care | C3: Dr. JIM Fitz | D3: IND-NPI-1001 | E3: GRP-NPI-9001 | F3: GRP-NPI-9001 | G3: IND-NPI-1001 | H3: SYN-TIN-001 | I3: Blue Cross | J3: BCBS01 | K3: Commercial | L3: NA | M3: Claims | N3: Completed | O3: Pending | P3: Not Started | Q3: No | R3: Pending | S3: 46147 | U3: Pending | V3: Individual NPI used instead of Group NPI | W3: NC00234 | X3: 46178 | Y3: Need to re-submit under Group NPI
A4: ENR-003 | B4: Northside Pediatrics | C4: Dr. Joel Fernandez | D4: IND-NPI-1002 | E4: GRP-NPI-9002 | F4: GRP-NPI-9002 | G4: GRP-NPI-9002 | H4: SYN-TIN-002 | I4: Medicaid | J4: MCD01 | K4: Government | L4: PTAN-002 | M4: Claims and ERA | N4: Completed | O4: Rejected | P4: Pending | Q4: Yes | R4: In Progress | S4: 46134 | U4: Blocked | V4: Medicaid additional enrollment is missing | W4: Js19731 | X4: 46177 | Y4: Additional Mediacaid enrollment required after
A5: ENR-004 | B5: Greenway Internal Medicine | C5: Dr. Daniel Lee | D5: IND-NPI-1003 | E5: GRP-NPI-9003 | F5: GRP-NPI-9003 | G5: GRP-NPI-9003 | H5: SYN-TIN-003 | I5: Aetna | J5: AET01 | K5: Commercial | L5: NA | M5: ERA | N5: Completed | O5: Approved | P5: Pending | Q5: No | R5: Pending | S5: 46154 | U5: Pending | V5: Clearinghouse portal not updated | W5: Nt92346 | X5: 46179 | Y5: ERA enrollment pending route update
A6: ENR-005 | B6: Lakeside Women Health | C6: Dr. Priya Shah | D6: IND-NPI-1004 | E6: GRP-NPI-9004 | F6: GRP-NPI-9004 | G6: GRP-NPI-9004 | H6: SYN-TIN-004 | I6: United Healthacare | J6: UHC01 | K6: Commercial | L6: NA | M6: Claims | N6: Completed | O6: Approved | P6: Not Required | Q6: Yes | R6: Completed | S6: 46127 | T6: 46141 | U6: Ready | V6: No Blocker | W6: NC00234 | X6: 46176 | Y6: Claims setup completed
A7: ENR-006 | B7: Hillcrest Orthopedics | C7: Dr. Mark Wilson | D7: IND-NPI-1005 | E7: GRP-NPI-9005 | F7: GRP-NPI-9005 | G7: GRP-NPI-9006 | H7: SYN-TIN-005 | I7: Cigna | J7: CIG01 | K7: Commercial | L7: NA | M7: Claims and ERA | N7: Completed | O7: Rejected | P7: Rejected | Q7: Yes | R7: Issue Found | S7: 46143 | U7: Blocked | V7: Credentialed NPI mismatch | W7: NC00234 | X7: 46180 | Y7: Enrolled group NPI does not match credentialed NPI
A8: ENR-007 | B8: Brightcare Cardiology | C8: Dr. Vivek Nair | D8: IND-NPI-1006 | E8: GRP-NPI-9006 | F8: GRP-NPI-9006 | G8: GRP-NPI-9006 | H8: SYN-TIN-006 | I8: Humana | J8: HUM01 | K8: Commercial | L8: NA | M8: ERA | N8: Completed | O8: Approved | P8: Approved | Q8: Yes | R8: Completed | S8: 46109 | T8: 46124 | U8: Ready | V8: No Blocker | W8: Nt92346 | X8: 46176 | Y8: ERS setup complete
A9: ENR-008 | B9: Cedar Grove Clinic | C9: Dr. Emily Chen | D9: IND-NPI-1007 | E9: GRP-NPI-9007 | F9: GRP-NPI-9007 | G9: GRP-NPI-9007 | H9: SYN-TIN-007 | I9: Medicare | J9: MED01 | K9: Government | L9: PTAN-OLD | M9: Claims and ERA | N9: Completed | O9: Rejected | P9: Pending | Q9: Yes | R9: In Progress | S9: 46137 | U9: Blocked | V9: Incorrect PTAN/Provider number | W9: Js19731 | X9: 46178 | Y9: Prcatice provided old PTAN
A10: ENR-009 | B10: Oak Street Primary Care | C10: Dr. Elizabeth Wanson | D10: IND-NPI-1008 | E10: GRP-NPI-9008 | F10: GRP-NPI-9008 | G10: GRP-NPI-9008 | H10: SYN-TIN-008 | I10: Blue Cross | J10: BC0001 | K10: Commercial | L10: NA | M10: Claims | N10: Completed | O10: Rejected | P10: Not started | Q10: Yes | R10: Issue Found | S10: 46150 | U10: Blocked | V10: Old Payer ID used | W10: Js19731 | X10: 46177 | Y10: need to update payer ID before cliams submission
A11: ENR-010 | B11: Westbrook Dermatology | C11: Dr. Sarah Marshall | D11: IND-NPI-1009 | E11: GRP-NPI-9009 | F11: GRP-NPI-9009 | G11: GRP-NPI-9009 | H11: SYN-TIN-009 | I11: Cigna | J11: CIG01 | K11: Commercial | L11: NA | M11: Claims and ERA | N11: In Progress | O11: Not Started | P11: Not Started | Q11: No | R11: Not Started | S11: 46162 | U11: Pending | V11: Credentialing not completed | W11: Nt92346 | X11: 46183 | Y11: Do not submit claims until credentialing is complete
A12: ENR-011 | B12: Summit Eye Care | C12: Dr. Alan Brooks | D12: IND-NPI-1010 | E12: GRP-NPI-9010 | F12: GRP-NPI-9010 | G12: IND-NPI-1010 | H12: SYN-TIN-010 | I12: United Healthacare | J12: UHC01 | K12: Commercial | L12: NA | M12: ERA | N12: Completed | O12: Approved | P12: Rejected | Q12: Yes | R12: Issue Found | S12: 46142 | U12: Blocked | V12: Individual NPI used instead of Group NPI | W12: Nt92346 | X12: 46179 | Y12: ERA rejected due to billing entity mismatch
A13: ENR-012 | B13: Pine Ridge Family Clinic | C13: Dr. Kavya Iyer | D13: IND-NPI-1011 | E13: GRP-NPI-9011 | F13: GRP-NPI-9011 | G13: GRP-NPI-9011 | H13: SYN-TIN-011 | I13: Aetna | J13: AET01 | K13: Commercial | L13: NA | M13: Claims and ERA | N13: Completed | O13: Pending | P13: Pending | Q13: Yes | R13: In Progress | S13: 46160 | U13: Pending | V13: Missing payer approval | W13: Nt92346 | X13: 46181 | Y13: waiting for payer approval
A14: ENR-013 | B14: Silverline Neurology | C14: Dr. Thomas Gray | D14: IND-NPI-1012 | E14: GRP-NPI-9012 | F14: GRP-NPI-9012 | G14: GRP-NPI-9012 | H14: SYN-TIN-012 | I14: Medicaid | J14: MCD02 | K14: Government | L14: PTAN-012 | M14: Claims | N14: Completed | O14: Approved | P14: Not Required | Q14: Yes | R14: Completed | S14: 46117 | T14: 46133 | U14: Ready | V14: No Blocker | W14: Js19731 | X14: 46176 | Y14: claims enrollment approved
A15: ENR-014 | B15: Maple Leaf Urgent Care | C15: Dr. Isla Fischer | D15: IND-NPI-1013 | E15: GRP-NPI-9013 | F15: GRP-NPI-9013 | G15: GRP-NPI-9013 | H15: SYN-TIN-013 | I15: Humana | J15: HUM01 | K15: Commercial | L15: NA | M15: Claims and ERA | N15: Completed | O15: Pending | P15: Pending | Q15: No | R15: Pending | S15: 46152 | U15: Pending | V15: Clearinghouse portal not updated | W15: NC00234 | X15: 46179 | Y15: Payer approved but portal route still pending
A16: ENR-015 | B16: Southview endocrinology | C16: Dr. Omar Ali | D16: IND-NPI-1014 | E16: GRP-NPI-9014 | F16: GRP-NPI-9014 | G16: GRP-NPI-9015 | H16: SYN-TIN-014 | I16: Medicare | J16: MED01 | K16: Government | L16: PTAN-014 | M16: Claims and ERA | N16: Completed | O16: Rejected | P16: Rejected | Q16: Yes | R16: Issue Found | S16: 46129 | U16: Blocked | V16: Credentialed NPI mismatch | W16: NC00234 | X16: 46178 | Y16: Wrong group NPI entered during enrollment
A17: ENR-016 | B17: Blue Harbor ENT | C17: Dr. Lily Morgan | D17: IND-NPI-1015 | E17: GRP-NPI-9015 | F17: GRP-NPI-9015 | G17: GRP-NPI-9015 | H17: SYN-TIN-015 | I17: Blue Cross | J17: BLU01 | K17: Commercial | L17: NA | M17: Claims | N17: Completed | O17: Approved | P17: Not Required | Q17: Yes | R17: Completed | S17: 46144 | T17: 46158 | U17: Ready | V17: No Blocker | W17: NC00234 | X17: 46176 | Y17: Ready for claims
A18: ENR-017 | B18: Valley View Gastro | C18: Dr. Sanjay Mehta | D18: IND-NPI-1016 | E18: GRP-NPI-9016 | F18: GRP-NPI-9016 | G18: GRP-NPI-9016 | H18: SYN-TIN-016 | I18: Cigna | J18: CIG01 | K18: Commercial | L18: NA | M18: ERA | N18: Completed | O18: Approved | P18: Pending | Q18: Yes | R18: In Progress | S18: 46153 | U18: Pending | V18: ERA Setup not completed | W18: Js19731 | X18: 46180 | Y18: ERA pending payer confirmation
A19: ENR-018 | B19: Riverside Behavioral Health | C19: Dr. Hannah scott | D19: IND-NPI-1017 | E19: GRP-NPI-9017 | F19: GRP-NPI-9017 | G19: GRP-NPI-9017 | H19: SYN-TIN-017 | I19: United Healthacare | J19: UNI01 | K19: Commercial | L19: NA | M19: Claims and ERA | N19: Completed | O19: Rejected | P19: Pending | Q19: Yes | R19: Issue Found | S19: 46148 | U19: Blocked | V19: Wrong Payer ID | W19: Js19731 | X19: 46177 | Y19: Incorrect payer ID used in enrollment
A20: ENR-019 | B20: Sunrise Family Medicine | C20: Dr. Alan Adams | D20: IND-NPI-1018 | E20: GRP-NPI-9018 | F20: GRP-NPI-9018 | G20: GRP-NPI-9018 | H20: SYN-TIN-018 | I20: Medicare | J20: MED01 | K20: Government | L20: PTAN-018 | M20: Claims and ERA | N20: Completed | O20: Pending | P20: Pending | Q20: Yes | R20: In Progress | S20: 46156 | U20: Pending | V20: Medicare additional enrollment missing | W20: Nt92346 | X20: 46182 | Y20: Additional Medicare step required
A21: ENR-020 | B21: Metro Spine Center | C21: Dr. Grace Miller | D21: IND-NPI-1019 | E21: GRP-NPI-9019 | F21: GRP-NPI-9019 | G21: GRP-NPI-9019 | H21: SYN-TIN-019 | I21: Aetna | J21: AET02 | K21: Commercial | L21: NA | M21: Claims and ERA | N21: Completed | O21: Approved | P21: Approved | Q21: Yes | R21: Completed | S21: 46121 | T21: 46136 | U21: Ready | V21: No Blocker | W21: Nt92346 | X21: 46176 | Y21: Claims and ERA ready
A22: ENR-021 | B22: Parkside Oncology | C22: Dr. Farah Ahmed | D22: IND-NPI-1020 | E22: GRP-NPI-9020 | F22: GRP-NPI-9020 | G22: IND-NPI-1020 | H22: SYN-TIN-020 | I22: Humana | J22: HUM02 | K22: Commercial | L22: NA | M22: Claims | N22: Completed | O22: Rejected | P22: Not Required | Q22: Yes | R22: Issue Found | S22: 46151 | U22: Blocked | V22: Individual NPI used instead of Group NPI | W22: Nt92346 | X22: 46179 | Y22: Claims enrollment submitted under individual NPI
A23: ENR-022 | B23: Eastwood Pulmonary | C23: Dr. Kevin Brown | D23: IND-NPI-1021 | E23: GRP-NPI-9021 | F23: GRP-NPI-9021 | G23: GRP-NPI-9021 | H23: SYN-TIN-021 | I23: Medicaid | J23: MCD002 | K23: Commercial | L23: PTAN-WRONG | M23: Claims and ERA | N23: Completed | O23: Rejected | P23: Pending | Q23: Yes | R23: Issue Found | S23: 46140 | U23: Blocked | V23: Incorrect PTAN/Provider number | W23: Nt92346 | X23: 46178 | Y23: Wrong Medicaid provider number entered
A24: ENR-023 | B24: Coral Springs Primary Care | C24: Dr. June mandarin | D24: IND-NPI-1022 | E24: GRP-NPI-9022 | F24: GRP-NPI-9022 | G24: GRP-NPI-9022 | H24: SYN-TIN-022 | I24: Blue Cross | J24: BLU02 | K24: Commercial | L24: NA | M24: ERA | N24: Completed | O24: Approved | P24: Pending | Q24: No | R24: Pending | S24: 46157 | U24: Pending | V24: Clearinghouse portal not updated | W24: ns | X24: 46181 | Y24: ERA route pending clearinghouse update
A25: ENR-024 | B25: Grand Oak Surgery Center | C25: Dr. Nathan Reed | D25: IND-NPI-1023 | E25: GRP-NPI-9023 | F25: GRP-NPI-9023 | G25: GRP-NPI-9023 | H25: SYN-TIN-023 | I25: Cigna | J25: CIG02 | K25: Commercial | L25: NA | M25: Claims and ERA | N25: In Progress | O25: Not Started | P25: Not Started | Q25: No | R25: Not Started | S25: 46164 | U25: Pending | V25: Credentialing not completed | W25: Js19731 | X25: 46184 | Y25: Credentialing still in progress
A26: ENR-025 | B26: Willow Creek Pediatrics | C26: Dr. Elena Torres | D26: IND-NPI-1024 | E26: GRP-NPI-9024 | F26: GRP-NPI-9024 | G26: GRP-NPI-9024 | H26: SYN-TIN-024 | I26: United Healthacare | J26: UNI02 | K26: Commercial | L26: NA | M26: Claims and ERA | N26: Completed | O26: Approved | P26: Approved | Q26: Yes | R26: Completed | S26: 46115 | T26: 46131 | U26: Ready | V26: No Blocker | W26: Nt92346 | X26: 46176 | Y26: Ready for claims and ERA

Sheet working_clean_data
A1: Record_ID | B1: Practice Name | C1: Provider Name | D1: Individual NPI | E1: Group NPI | F1: Credentialed NPI | G1: Enrolled NPI | H1: Tax ID | I1: Payer Name | J1: Payer ID | K1: Payer Type | L1: PTAN/Provider number | M1: Enrollment Type | N1: Credentialing status | O1: Claims_Enrollment_Status | P1: ERA Enrollment Status | Q1: EEP updated? | R1: EEP Status | S1: Submitted Date | T1: Approved date | U1: Current Status | V1: Blocked reason | W1: Assigned Owner | X1: Follow-up Date | Y1: Notes | Z1: Aging Days | AA1: SLA Status | AB1: NPI Match Status | AC1: Provider Identifier Issue Flag | AD1: Payer Routing issue Flag | AE1: Clearinghouse gap Flag | AF1: Government Payer Issue Flag | AG1: Claims Ready Flag | AH1: ERA Ready Flag | AI1: Action Required Flag
A2: ENR-001 | B2: River Valley Family Care | C2: Dr. JIM Fitz | D2: IND-NPI-1001 | E2: GRP-NPI-9001 | F2: GRP-NPI-9001 | G2: GRP-NPI-9001 | H2: SYN-TIN-001 | I2: Medicare | J2: MED01 | K2: Government | L2: PTAN-001 | M2: Claims and ERA | N2: Completed | O2: Approved | P2: Approved | Q2: Yes | R2: Completed | S2: 46113 | T2: 46130 | U2: Ready | V2: No Blocker | W2: Nt92346 | X2: 46176 | Y2: Ready for claims and ERA | Z2: =IF(tblEnrollment[[#This Row],[Approved date]]="",DATE(2026,6,3)-tblEnrollment[[#This Row],[Submitted Date]],tblEnrollment[[#This Row],[Approved date]]-tblEnrollment[[#This Row],[Submitted Date]]) -> 17 | AA2: =IF(tblEnrollment[[#This Row],[Current Status]] ="Ready","Completed",IF(Z2>21,"SLA Breached","Within SLA")) -> Completed | AB2: =IF(tblEnrollment[[#This Row],[Credentialed NPI]] =tblEnrollment[[#This Row],[Enrolled NPI]],"NPI Match","NPI Mismatch") -> NPI Match | AC2: =IF(OR(tblEnrollment[[#This Row],[Blocked reason]] ="Individual NPI used instead of Group NPI",tblEnrollment[[#This Row],[Blocked reason]] ="Credentialed NPI mismatch",tblEnrollment[[#This Row],[Blocked reason]] ="Incorrect PTAN/Provider number"),"Yes","No") -> No | AD2: =IF(OR(tblEnrollment[[#This Row],[Blocked reason]] ="Wrong Payer ID",tblEnrollment[[#This Row],[Blocked reason]] ="Old Payer ID used"),"Yes","No") -> No | AE2: =IF(OR(tblEnrollment[[#This Row],[EEP updated?]]="No",tblEnrollment[[#This Row],[Blocked reason]] ="Clearinghouse portal not updated"),"Yes","No") -> No | AF2: =IF(OR(tblEnrollment[[#This Row],[Blocked reason]] ="Medicaid additional enrollment is missing",tblEnrollment[[#This Row],[Blocked reason]] ="Incorrect PTAN/Provider number",tblEnrollment[[#This Row],[Blocked reason]] ="Medicare additional enrollment missing"),"Yes","No") -> No | AG2: =IF(OR(tblEnrollment[[#This Row],[Enrollment Type ]]="Claims",tblEnrollment[[#This Row],[Enrollment Type ]]="Claims and ERA"),IF(AND(tblEnrollment[[#This Row],[Credentialing status]]="Completed",tblEnrollment[[#This Row],[Claims_Enrollment_Status]]="Approved",tblEnrollment[[#This Row],[EEP Status]]="Completed",AB2="NPI Match"),"Ready","Not Ready"),"Not Applicable") -> Ready | AH2: =IF(OR(tblEnrollment[[#This Row],[Enrollment Type ]]="ERA",tblEnrollment[[#This Row],[Enrollment Type ]]="Claims and ERA"),IF(AND(tblEnrollment[[#This Row],[Credentialing status]]="Completed",tblEnrollment[[#This Row],[ERA Enrollment Status]]="Approved",tblEnrollment[[#This Row],[EEP Status]]="Completed",AB2="NPI Match"),"Ready","Not Ready"),"Not Applicable") -> Ready | AI2: =IF(tblEnrollment[[#This Row],[Blocked reason]] ="No Blocker","No","Yes") -> No
A3: ENR-002 | B3: River Valley Family Care | C3: Dr. JIM Fitz | D3: IND-NPI-1001 | E3: GRP-NPI-9001 | F3: GRP-NPI-9001 | G3: IND-NPI-1001 | H3: SYN-TIN-001 | I3: Blue Cross | J3: BCBS01 | K3: Commercial | L3: NA | M3: Claims | N3: Completed | O3: Pending | P3: Not Started | Q3: No | R3: Pending | S3: 46147 | U3: Pending | V3: Individual NPI used instead of Group NPI | W3: NC00234 | X3: 46178 | Y3: Need to re-submit under Group NPI | Z3: =IF(tblEnrollment[[#This Row],[Approved date]]="",DATE(2026,6,3)-tblEnrollment[[#This Row],[Submitted Date]],tblEnrollment[[#This Row],[Approved date]]-tblEnrollment[[#This Row],[Submitted Date]]) -> 29 | AA3: =IF(tblEnrollment[[#This Row],[Current Status]] ="Ready","Completed",IF(Z3>21,"SLA Breached","Within SLA")) -> SLA Breached | AB3: =IF(tblEnrollment[[#This Row],[Credentialed NPI]] =tblEnrollment[[#This Row],[Enrolled NPI]],"NPI Match","NPI Mismatch") -> NPI Mismatch | AC3: =IF(OR(tblEnrollment[[#This Row],[Blocked reason]] ="Individual NPI used instead of Group NPI",tblEnrollment[[#This Row],[Blocked reason]] ="Credentialed NPI mismatch",tblEnrollment[[#This Row],[Blocked reason]] ="Incorrect PTAN/Provider number"),"Yes","No") -> Yes | AD3: =IF(OR(tblEnrollment[[#This Row],[Blocked reason]] ="Wrong Payer ID",tblEnrollment[[#This Row],[Blocked reason]] ="Old Payer ID used"),"Yes","No") -> No | AE3: =IF(OR(tblEnrollment[[#This Row],[EEP updated?]]="No",tblEnrollment[[#This Row],[Blocked reason]] ="Clearinghouse portal not updated"),"Yes","No") -> Yes | AF3: =IF(OR(tblEnrollment[[#This Row],[Blocked reason]] ="Medicaid additional enrollment is missing",tblEnrollment[[#This Row],[Blocked reason]] ="Incorrect PTAN/Provider number",tblEnrollment[[#This Row],[Blocked reason]] ="Medicare additional enrollment missing"),"Yes","No") -> No | AG3: =IF(OR(tblEnrollment[[#This Row],[Enrollment Type ]]="Claims",tblEnrollment[[#This Row],[Enrollment Type ]]="Claims and ERA"),IF(AND(tblEnrollment[[#This Row],[Credentialing status]]="Completed",tblEnrollment[[#This Row],[Claims_Enrollment_Status]]="Approved",tblEnrollment[[#This Row],[EEP Status]]="Completed",AB3="NPI Match"),"Ready","Not Ready"),"Not Applicable") -> Not Ready | AH3: =IF(OR(tblEnrollment[[#This Row],[Enrollment Type ]]="ERA",tblEnrollment[[#This Row],[Enrollment Type ]]="Claims and ERA"),IF(AND(tblEnrollment[[#This Row],[Credentialing status]]="Completed",tblEnrollment[[#This Row],[ERA Enrollment Status]]="Approved",tblEnrollment[[#This Row],[EEP Status]]="Completed",AB3="NPI Match"),"Ready","Not Ready"),"Not Applicable") -> Not Applicable | AI3: =IF(tblEnrollment[[#This Row],[Blocked reason]] ="No Blocker","No","Yes") -> Yes
A4: ENR-003 | B4: Northside Pediatrics | C4: Dr. Joel Fernandez | D4: IND-NPI-1002 | E4: GRP-NPI-9002 | F4: GRP-NPI-9002 | G4: GRP-NPI-9002 | H4: SYN-TIN-002 | I4: Medicaid | J4: MCD01 | K4: Government | L4: PTAN-002 | M4: Claims and ERA | N4: Completed | O4: Rejected | P4: Pending | Q4: Yes | R4: In Progress | S4: 46134 | U4: Blocked | V4: Medicaid additional enrollment is missing | W4: Js19731 | X4: 46177 | Y4: Additional Mediacaid enrollment required after | Z4: =IF(tblEnrollment[[#This Row],[Approved date]]="",DATE(2026,6,3)-tblEnrollment[[#This Row],[Submitted Date]],tblEnrollment[[#This Row],[Approved date]]-tblEnrollment[[#This Row],[Submitted Date]]) -> 42 | AA4: =IF(tblEnrollment[[#This Row],[Current Status]] ="Ready","Completed",IF(Z4>21,"SLA Breached","Within SLA")) -> SLA Breached | AB4: =IF(tblEnrollment[[#This Row],[Credentialed NPI]] =tblEnrollment[[#This Row],[Enrolled NPI]],"NPI Match","NPI Mismatch") -> NPI Match | AC4: =IF(OR(tblEnrollment[[#This Row],[Blocked reason]] ="Individual NPI used instead of Group NPI",tblEnrollment[[#This Row],[Blocked reason]] ="Credentialed NPI mismatch",tblEnrollment[[#This Row],[Blocked reason]] ="Incorrect PTAN/Provider number"),"Yes","No") -> No | AD4: =IF(OR(tblEnrollment[[#This Row],[Blocked reason]] ="Wrong Payer ID",tblEnrollment[[#This Row],[Blocked reason]] ="Old Payer ID used"),"Yes","No") -> No | AE4: =IF(OR(tblEnrollment[[#This Row],[EEP updated?]]="No",tblEnrollment[[#This Row],[Blocked reason]] ="Clearinghouse portal not updated"),"Yes","No") -> No | AF4: =IF(OR(tblEnrollment[[#This Row],[Blocked reason]] ="Medicaid additional enrollment is missing",tblEnrollment[[#This Row],[Blocked reason]] ="Incorrect PTAN/Provider number",tblEnrollment[[#This Row],[Blocked reason]] ="Medicare additional enrollment missing"),"Yes","No") -> Yes | AG4: =IF(OR(tblEnrollment[[#This Row],[Enrollment Type ]]="Claims",tblEnrollment[[#This Row],[Enrollment Type ]]="Claims and ERA"),IF(AND(tblEnrollment[[#This Row],[Credentialing status]]="Completed",tblEnrollment[[#This Row],[Claims_Enrollment_Status]]="Approved",tblEnrollment[[#This Row],[EEP Status]]="Completed",AB4="NPI Match"),"Ready","Not Ready"),"Not Applicable") -> Not Ready | AH4: =IF(OR(tblEnrollment[[#This Row],[Enrollment Type ]]="ERA",tblEnrollment[[#This Row],[Enrollment Type ]]="Claims and ERA"),IF(AND(tblEnrollment[[#This Row],[Credentialing status]]="Completed",tblEnrollment[[#This Row],[ERA Enrollment Status]]="Approved",tblEnrollment[[#This Row],[EEP Status]]="Completed",AB4="NPI Match"),"Ready","Not Ready"),"Not Applicable") -> Not Ready | AI4: =IF(tblEnrollment[[#This Row],[Blocked reason]] ="No Blocker","No","Yes") -> Yes
A5: ENR-004 | B5: Greenway Internal Medicine | C5: Dr. Daniel Lee | D5: IND-NPI-1003 | E5: GRP-NPI-9003 | F5: GRP-NPI-9003 | G5: GRP-NPI-9003 | H5: SYN-TIN-003 | I5: Aetna | J5: AET01 | K5: Commercial | L5: NA | M5: ERA | N5: Completed | O5: Approved | P5: Pending | Q5: No | R5: Pending | S5: 46154 | U5: Pending | V5: Clearinghouse portal not updated | W5: Nt92346 | X5: 46179 | Y5: ERA enrollment pending route update | Z5: =IF(tblEnrollment[[#This Row],[Approved date]]="",DATE(2026,6,3)-tblEnrollment[[#This Row],[Submitted Date]],tblEnrollment[[#This Row],[Approved date]]-tblEnrollment[[#This Row],[Submitted Date]]) -> 22 | AA5: =IF(tblEnrollment[[#This Row],[Current Status]] ="Ready","Completed",IF(Z5>21,"SLA Breached","Within SLA")) -> SLA Breached | AB5: =IF(tblEnrollment[[#This Row],[Credentialed NPI]] =tblEnrollment[[#This Row],[Enrolled NPI]],"NPI Match","NPI Mismatch") -> NPI Match | AC5: =IF(OR(tblEnrollment[[#This Row],[Blocked reason]] ="Individual NPI used instead of Group NPI",tblEnrollment[[#This Row],[Blocked reason]] ="Credentialed NPI mismatch",tblEnrollment[[#This Row],[Blocked reason]] ="Incorrect PTAN/Provider number"),"Yes","No") -> No | AD5: =IF(OR(tblEnrollment[[#This Row],[Blocked reason]] ="Wrong Payer ID",tblEnrollment[[#This Row],[Blocked reason]] ="Old Payer ID used"),"Yes","No") -> No | AE5: =IF(OR(tblEnrollment[[#This Row],[EEP updated?]]="No",tblEnrollment[[#This Row],[Blocked reason]] ="Clearinghouse portal not updated"),"Yes","No") -> Yes | AF5: =IF(OR(tblEnrollment[[#This Row],[Blocked reason]] ="Medicaid additional enrollment is missing",tblEnrollment[[#This Row],[Blocked reason]] ="Incorrect PTAN/Provider number",tblEnrollment[[#This Row],[Blocked reason]] ="Medicare additional enrollment missing"),"Yes","No") -> No | AG5: =IF(OR(tblEnrollment[[#This Row],[Enrollment Type ]]="Claims",tblEnrollment[[#This Row],[Enrollment Type ]]="Claims and ERA"),IF(AND(tblEnrollment[[#This Row],[Credentialing status]]="Completed",tblEnrollment[[#This Row],[Claims_Enrollment_Status]]="Approved",tblEnrollment[[#This Row],[EEP Status]]="Completed",AB5="NPI Match"),"Ready","Not Ready"),"Not Applicable") -> Not Applicable | AH5: =IF(OR(tblEnrollment[[#This Row],[Enrollment Type ]]="ERA",tblEnrollment[[#This Row],[Enrollment Type ]]="Claims and ERA"),IF(AND(tblEnrollment[[#This Row],[Credentialing status]]="Completed",tblEnrollment[[#This Row],[ERA Enrollment Status]]="Approved",tblEnrollment[[#This Row],[EEP Status]]="Completed",AB5="NPI Match"),"Ready","Not Ready"),"Not Applicable") -> Not Ready | AI5: =IF(tblEnrollment[[#This Row],[Blocked reason]] ="No Blocker","No","Yes") -> Yes
A6: ENR-005 | B6: Lakeside Women Health | C6: Dr. Priya Shah | D6: IND-NPI-1004 | E6: GRP-NPI-9004 | F6: GRP-NPI-9004 | G6: GRP-NPI-9004 | H6: SYN-TIN-004 | I6: United Healthacare | J6: UHC01 | K6: Commercial | L6: NA | M6: Claims | N6: Completed | O6: Approved | P6: Not Required | Q6: Yes | R6: Completed | S6: 46127 | T6: 46141 | U6: Ready | V6: No Blocker | W6: NC00234 | X6: 46176 | Y6: Claims setup completed | Z6: =IF(tblEnrollment[[#This Row],[Approved date]]="",DATE(2026,6,3)-tblEnrollment[[#This Row],[Submitted Date]],tblEnrollment[[#This Row],[Approved date]]-tblEnrollment[[#This Row],[Submitted Date]]) -> 14 | AA6: =IF(tblEnrollment[[#This Row],[Current Status]] ="Ready","Completed",IF(Z6>21,"SLA Breached","Within SLA")) -> Completed | AB6: =IF(tblEnrollment[[#This Row],[Credentialed NPI]] =tblEnrollment[[#This Row],[Enrolled NPI]],"NPI Match","NPI Mismatch") -> NPI Match | AC6: =IF(OR(tblEnrollment[[#This Row],[Blocked reason]] ="Individual NPI used instead of Group NPI",tblEnrollment[[#This Row],[Blocked reason]] ="Credentialed NPI mismatch",tblEnrollment[[#This Row],[Blocked reason]] ="Incorrect PTAN/Provider number"),"Yes","No") -> No | AD6: =IF(OR(tblEnrollment[[#This Row],[Blocked reason]] ="Wrong Payer ID",tblEnrollment[[#This Row],[Blocked reason]] ="Old Payer ID used"),"Yes","No") -> No | AE6: =IF(OR(tblEnrollment[[#This Row],[EEP updated?]]="No",tblEnrollment[[#This Row],[Blocked reason]] ="Clearinghouse portal not updated"),"Yes","No") -> No | AF6: =IF(OR(tblEnrollment[[#This Row],[Blocked reason]] ="Medicaid additional enrollment is missing",tblEnrollment[[#This Row],[Blocked reason]] ="Incorrect PTAN/Provider number",tblEnrollment[[#This Row],[Blocked reason]] ="Medicare additional enrollment missing"),"Yes","No") -> No | AG6: =IF(OR(tblEnrollment[[#This Row],[Enrollment Type ]]="Claims",tblEnrollment[[#This Row],[Enrollment Type ]]="Claims and ERA"),IF(AND(tblEnrollment[[#This Row],[Credentialing status]]="Completed",tblEnrollment[[#This Row],[Claims_Enrollment_Status]]="Approved",tblEnrollment[[#This Row],[EEP Status]]="Completed",AB6="NPI Match"),"Ready","Not Ready"),"Not Applicable") -> Ready | AH6: =IF(OR(tblEnrollment[[#This Row],[Enrollment Type ]]="ERA",tblEnrollment[[#This Row],[Enrollment Type ]]="Claims and ERA"),IF(AND(tblEnrollment[[#This Row],[Credentialing status]]="Completed",tblEnrollment[[#This Row],[ERA Enrollment Status]]="Approved",tblEnrollment[[#This Row],[EEP Status]]="Completed",AB6="NPI Match"),"Ready","Not Ready"),"Not Applicable") -> Not Applicable | AI6: =IF(tblEnrollment[[#This Row],[Blocked reason]] ="No Blocker","No","Yes") -> No
A7: ENR-006 | B7: Hillcrest Orthopedics | C7: Dr. Mark Wilson | D7: IND-NPI-1005 | E7: GRP-NPI-9005 | F7: GRP-NPI-9005 | G7: GRP-NPI-9006 | H7: SYN-TIN-005 | I7: Cigna | J7: CIG01 | K7: Commercial | L7: NA | M7: Claims and ERA | N7: Completed | O7: Rejected | P7: Rejected | Q7: Yes | R7: Issue Found | S7: 46143 | U7: Blocked | V7: Credentialed NPI mismatch | W7: NC00234 | X7: 46180 | Y7: Enrolled group NPI does not match credentialed NPI | Z7: =IF(tblEnrollment[[#This Row],[Approved date]]="",DATE(2026,6,3)-tblEnrollment[[#This Row],[Submitted Date]],tblEnrollment[[#This Row],[Approved date]]-tblEnrollment[[#This Row],[Submitted Date]]) -> 33 | AA7: =IF(tblEnrollment[[#This Row],[Current Status]] ="Ready","Completed",IF(Z7>21,"SLA Breached","Within SLA")) -> SLA Breached | AB7: =IF(tblEnrollment[[#This Row],[Credentialed NPI]] =tblEnrollment[[#This Row],[Enrolled NPI]],"NPI Match","NPI Mismatch") -> NPI Mismatch | AC7: =IF(OR(tblEnrollment[[#This Row],[Blocked reason]] ="Individual NPI used instead of Group NPI",tblEnrollment[[#This Row],[Blocked reason]] ="Credentialed NPI mismatch",tblEnrollment[[#This Row],[Blocked reason]] ="Incorrect PTAN/Provider number"),"Yes","No") -> Yes | AD7: =IF(OR(tblEnrollment[[#This Row],[Blocked reason]] ="Wrong Payer ID",tblEnrollment[[#This Row],[Blocked reason]] ="Old Payer ID used"),"Yes","No") -> No | AE7: =IF(OR(tblEnrollment[[#This Row],[EEP updated?]]="No",tblEnrollment[[#This Row],[Blocked reason]] ="Clearinghouse portal not updated"),"Yes","No") -> No | AF7: =IF(OR(tblEnrollment[[#This Row],[Blocked reason]] ="Medicaid additional enrollment is missing",tblEnrollment[[#This Row],[Blocked reason]] ="Incorrect PTAN/Provider number",tblEnrollment[[#This Row],[Blocked reason]] ="Medicare additional enrollment missing"),"Yes","No") -> No | AG7: =IF(OR(tblEnrollment[[#This Row],[Enrollment Type ]]="Claims",tblEnrollment[[#This Row],[Enrollment Type ]]="Claims and ERA"),IF(AND(tblEnrollment[[#This Row],[Credentialing status]]="Completed",tblEnrollment[[#This Row],[Claims_Enrollment_Status]]="Approved",tblEnrollment[[#This Row],[EEP Status]]="Completed",AB7="NPI Match"),"Ready","Not Ready"),"Not Applicable") -> Not Ready | AH7: =IF(OR(tblEnrollment[[#This Row],[Enrollment Type ]]="ERA",tblEnrollment[[#This Row],[Enrollment Type ]]="Claims and ERA"),IF(AND(tblEnrollment[[#This Row],[Credentialing status]]="Completed",tblEnrollment[[#This Row],[ERA Enrollment Status]]="Approved",tblEnrollment[[#This Row],[EEP Status]]="Completed",AB7="NPI Match"),"Ready","Not Ready"),"Not Applicable") -> Not Ready | AI7: =IF(tblEnrollment[[#This Row],[Blocked reason]] ="No Blocker","No","Yes") -> Yes
A8: ENR-007 | B8: Brightcare Cardiology | C8: Dr. Vivek Nair | D8: IND-NPI-1006 | E8: GRP-NPI-9006 | F8: GRP-NPI-9006 | G8: GRP-NPI-9006 | H8: SYN-TIN-006 | I8: Humana | J8: HUM01 | K8: Commercial | L8: NA | M8: ERA | N8: Completed | O8: Approved | P8: Approved | Q8: Yes | R8: Completed | S8: 46109 | T8: 46124 | U8: Ready | V8: No Blocker | W8: Nt92346 | X8: 46176 | Y8: ERS setup complete | Z8: =IF(tblEnrollment[[#This Row],[Approved date]]="",DATE(2026,6,3)-tblEnrollment[[#This Row],[Submitted Date]],tblEnrollment[[#This Row],[Approved date]]-tblEnrollment[[#This Row],[Submitted Date]]) -> 15 | AA8: =IF(tblEnrollment[[#This Row],[Current Status]] ="Ready","Completed",IF(Z8>21,"SLA Breached","Within SLA")) -> Completed | AB8: =IF(tblEnrollment[[#This Row],[Credentialed NPI]] =tblEnrollment[[#This Row],[Enrolled NPI]],"NPI Match","NPI Mismatch") -> NPI Match | AC8: =IF(OR(tblEnrollment[[#This Row],[Blocked reason]] ="Individual NPI used instead of Group NPI",tblEnrollment[[#This Row],[Blocked reason]] ="Credentialed NPI mismatch",tblEnrollment[[#This Row],[Blocked reason]] ="Incorrect PTAN/Provider number"),"Yes","No") -> No | AD8: =IF(OR(tblEnrollment[[#This Row],[Blocked reason]] ="Wrong Payer ID",tblEnrollment[[#This Row],[Blocked reason]] ="Old Payer ID used"),"Yes","No") -> No | AE8: =IF(OR(tblEnrollment[[#This Row],[EEP updated?]]="No",tblEnrollment[[#This Row],[Blocked reason]] ="Clearinghouse portal not updated"),"Yes","No") -> No | AF8: =IF(OR(tblEnrollment[[#This Row],[Blocked reason]] ="Medicaid additional enrollment is missing",tblEnrollment[[#This Row],[Blocked reason]] ="Incorrect PTAN/Provider number",tblEnrollment[[#This Row],[Blocked reason]] ="Medicare additional enrollment missing"),"Yes","No") -> No | AG8: =IF(OR(tblEnrollment[[#This Row],[Enrollment Type ]]="Claims",tblEnrollment[[#This Row],[Enrollment Type ]]="Claims and ERA"),IF(AND(tblEnrollment[[#This Row],[Credentialing status]]="Completed",tblEnrollment[[#This Row],[Claims_Enrollment_Status]]="Approved",tblEnrollment[[#This Row],[EEP Status]]="Completed",AB8="NPI Match"),"Ready","Not Ready"),"Not Applicable") -> Not Applicable | AH8: =IF(OR(tblEnrollment[[#This Row],[Enrollment Type ]]="ERA",tblEnrollment[[#This Row],[Enrollment Type ]]="Claims and ERA"),IF(AND(tblEnrollment[[#This Row],[Credentialing status]]="Completed",tblEnrollment[[#This Row],[ERA Enrollment Status]]="Approved",tblEnrollment[[#This Row],[EEP Status]]="Completed",AB8="NPI Match"),"Ready","Not Ready"),"Not Applicable") -> Ready | AI8: =IF(tblEnrollment[[#This Row],[Blocked reason]] ="No Blocker","No","Yes") -> No
A9: ENR-008 | B9: Cedar Grove Clinic | C9: Dr. Emily Chen | D9: IND-NPI-1007 | E9: GRP-NPI-9007 | F9: GRP-NPI-9007 | G9: GRP-NPI-9007 | H9: SYN-TIN-007 | I9: Medicare | J9: MED01 | K9: Government | L9: PTAN-OLD | M9: Claims and ERA | N9: Completed | O9: Rejected | P9: Pending | Q9: Yes | R9: In Progress | S9: 46137 | U9: Blocked | V9: Incorrect PTAN/Provider number | W9: Js19731 | X9: 46178 | Y9: Prcatice provided old PTAN | Z9: =IF(tblEnrollment[[#This Row],[Approved date]]="",DATE(2026,6,3)-tblEnrollment[[#This Row],[Submitted Date]],tblEnrollment[[#This Row],[Approved date]]-tblEnrollment[[#This Row],[Submitted Date]]) -> 39 | AA9: =IF(tblEnrollment[[#This Row],[Current Status]] ="Ready","Completed",IF(Z9>21,"SLA Breached","Within SLA")) -> SLA Breached | AB9: =IF(tblEnrollment[[#This Row],[Credentialed NPI]] =tblEnrollment[[#This Row],[Enrolled NPI]],"NPI Match","NPI Mismatch") -> NPI Match | AC9: =IF(OR(tblEnrollment[[#This Row],[Blocked reason]] ="Individual NPI used instead of Group NPI",tblEnrollment[[#This Row],[Blocked reason]] ="Credentialed NPI mismatch",tblEnrollment[[#This Row],[Blocked reason]] ="Incorrect PTAN/Provider number"),"Yes","No") -> Yes | AD9: =IF(OR(tblEnrollment[[#This Row],[Blocked reason]] ="Wrong Payer ID",tblEnrollment[[#This Row],[Blocked reason]] ="Old Payer ID used"),"Yes","No") -> No | AE9: =IF(OR(tblEnrollment[[#This Row],[EEP updated?]]="No",tblEnrollment[[#This Row],[Blocked reason]] ="Clearinghouse portal not updated"),"Yes","No") -> No | AF9: =IF(OR(tblEnrollment[[#This Row],[Blocked reason]] ="Medicaid additional enrollment is missing",tblEnrollment[[#This Row],[Blocked reason]] ="Incorrect PTAN/Provider number",tblEnrollment[[#This Row],[Blocked reason]] ="Medicare additional enrollment missing"),"Yes","No") -> Yes | AG9: =IF(OR(tblEnrollment[[#This Row],[Enrollment Type ]]="Claims",tblEnrollment[[#This Row],[Enrollment Type ]]="Claims and ERA"),IF(AND(tblEnrollment[[#This Row],[Credentialing status]]="Completed",tblEnrollment[[#This Row],[Claims_Enrollment_Status]]="Approved",tblEnrollment[[#This Row],[EEP Status]]="Completed",AB9="NPI Match"),"Ready","Not Ready"),"Not Applicable") -> Not Ready | AH9: =IF(OR(tblEnrollment[[#This Row],[Enrollment Type ]]="ERA",tblEnrollment[[#This Row],[Enrollment Type ]]="Claims and ERA"),IF(AND(tblEnrollment[[#This Row],[Credentialing status]]="Completed",tblEnrollment[[#This Row],[ERA Enrollment Status]]="Approved",tblEnrollment[[#This Row],[EEP Status]]="Completed",AB9="NPI Match"),"Ready","Not Ready"),"Not Applicable") -> Not Ready | AI9: =IF(tblEnrollment[[#This Row],[Blocked reason]] ="No Blocker","No","Yes") -> Yes
A10: ENR-009 | B10: Oak Street Primary Care | C10: Dr. Elizabeth Wanson | D10: IND-NPI-1008 | E10: GRP-NPI-9008 | F10: GRP-NPI-9008 | G10: GRP-NPI-9008 | H10: SYN-TIN-008 | I10: Blue Cross | J10: BC0001 | K10: Commercial | L10: NA | M10: Claims | N10: Completed | O10: Rejected | P10: Not started | Q10: Yes | R10: Issue Found | S10: 46150 | U10: Blocked | V10: Old Payer ID used | W10: Js19731 | X10: 46177 | Y10: need to update payer ID before cliams submission | Z10: =IF(tblEnrollment[[#This Row],[Approved date]]="",DATE(2026,6,3)-tblEnrollment[[#This Row],[Submitted Date]],tblEnrollment[[#This Row],[Approved date]]-tblEnrollment[[#This Row],[Submitted Date]]) -> 26 | AA10: =IF(tblEnrollment[[#This Row],[Current Status]] ="Ready","Completed",IF(Z10>21,"SLA Breached","Within SLA")) -> SLA Breached | AB10: =IF(tblEnrollment[[#This Row],[Credentialed NPI]] =tblEnrollment[[#This Row],[Enrolled NPI]],"NPI Match","NPI Mismatch") -> NPI Match | AC10: =IF(OR(tblEnrollment[[#This Row],[Blocked reason]] ="Individual NPI used instead of Group NPI",tblEnrollment[[#This Row],[Blocked reason]] ="Credentialed NPI mismatch",tblEnrollment[[#This Row],[Blocked reason]] ="Incorrect PTAN/Provider number"),"Yes","No") -> No | AD10: =IF(OR(tblEnrollment[[#This Row],[Blocked reason]] ="Wrong Payer ID",tblEnrollment[[#This Row],[Blocked reason]] ="Old Payer ID used"),"Yes","No") -> Yes | AE10: =IF(OR(tblEnrollment[[#This Row],[EEP updated?]]="No",tblEnrollment[[#This Row],[Blocked reason]] ="Clearinghouse portal not updated"),"Yes","No") -> No | AF10: =IF(OR(tblEnrollment[[#This Row],[Blocked reason]] ="Medicaid additional enrollment is missing",tblEnrollment[[#This Row],[Blocked reason]] ="Incorrect PTAN/Provider number",tblEnrollment[[#This Row],[Blocked reason]] ="Medicare additional enrollment missing"),"Yes","No") -> No | AG10: =IF(OR(tblEnrollment[[#This Row],[Enrollment Type ]]="Claims",tblEnrollment[[#This Row],[Enrollment Type ]]="Claims and ERA"),IF(AND(tblEnrollment[[#This Row],[Credentialing status]]="Completed",tblEnrollment[[#This Row],[Claims_Enrollment_Status]]="Approved",tblEnrollment[[#This Row],[EEP Status]]="Completed",AB10="NPI Match"),"Ready","Not Ready"),"Not Applicable") -> Not Ready | AH10: =IF(OR(tblEnrollment[[#This Row],[Enrollment Type ]]="ERA",tblEnrollment[[#This Row],[Enrollment Type ]]="Claims and ERA"),IF(AND(tblEnrollment[[#This Row],[Credentialing status]]="Completed",tblEnrollment[[#This Row],[ERA Enrollment Status]]="Approved",tblEnrollment[[#This Row],[EEP Status]]="Completed",AB10="NPI Match"),"Ready","Not Ready"),"Not Applicable") -> Not Applicable | AI10: =IF(tblEnrollment[[#This Row],[Blocked reason]] ="No Blocker","No","Yes") -> Yes
A11: ENR-010 | B11: Westbrook Dermatology | C11: Dr. Sarah Marshall | D11: IND-NPI-1009 | E11: GRP-NPI-9009 | F11: GRP-NPI-9009 | G11: GRP-NPI-9009 | H11: SYN-TIN-009 | I11: Cigna | J11: CIG01 | K11: Commercial | L11: NA | M11: Claims and ERA | N11: In Progress | O11: Not Started | P11: Not Started | Q11: No | R11: Not Started | S11: 46162 | U11: Pending | V11: Credentialing not completed | W11: Nt92346 | X11: 46183 | Y11: Do not submit claims until credentialing is complete | Z11: =IF(tblEnrollment[[#This Row],[Approved date]]="",DATE(2026,6,3)-tblEnrollment[[#This Row],[Submitted Date]],tblEnrollment[[#This Row],[Approved date]]-tblEnrollment[[#This Row],[Submitted Date]]) -> 14 | AA11: =IF(tblEnrollment[[#This Row],[Current Status]] ="Ready","Completed",IF(Z11>21,"SLA Breached","Within SLA")) -> Within SLA | AB11: =IF(tblEnrollment[[#This Row],[Credentialed NPI]] =tblEnrollment[[#This Row],[Enrolled NPI]],"NPI Match","NPI Mismatch") -> NPI Match | AC11: =IF(OR(tblEnrollment[[#This Row],[Blocked reason]] ="Individual NPI used instead of Group NPI",tblEnrollment[[#This Row],[Blocked reason]] ="Credentialed NPI mismatch",tblEnrollment[[#This Row],[Blocked reason]] ="Incorrect PTAN/Provider number"),"Yes","No") -> No | AD11: =IF(OR(tblEnrollment[[#This Row],[Blocked reason]] ="Wrong Payer ID",tblEnrollment[[#This Row],[Blocked reason]] ="Old Payer ID used"),"Yes","No") -> No | AE11: =IF(OR(tblEnrollment[[#This Row],[EEP updated?]]="No",tblEnrollment[[#This Row],[Blocked reason]] ="Clearinghouse portal not updated"),"Yes","No") -> Yes | AF11: =IF(OR(tblEnrollment[[#This Row],[Blocked reason]] ="Medicaid additional enrollment is missing",tblEnrollment[[#This Row],[Blocked reason]] ="Incorrect PTAN/Provider number",tblEnrollment[[#This Row],[Blocked reason]] ="Medicare additional enrollment missing"),"Yes","No") -> No | AG11: =IF(OR(tblEnrollment[[#This Row],[Enrollment Type ]]="Claims",tblEnrollment[[#This Row],[Enrollment Type ]]="Claims and ERA"),IF(AND(tblEnrollment[[#This Row],[Credentialing status]]="Completed",tblEnrollment[[#This Row],[Claims_Enrollment_Status]]="Approved",tblEnrollment[[#This Row],[EEP Status]]="Completed",AB11="NPI Match"),"Ready","Not Ready"),"Not Applicable") -> Not Ready | AH11: =IF(OR(tblEnrollment[[#This Row],[Enrollment Type ]]="ERA",tblEnrollment[[#This Row],[Enrollment Type ]]="Claims and ERA"),IF(AND(tblEnrollment[[#This Row],[Credentialing status]]="Completed",tblEnrollment[[#This Row],[ERA Enrollment Status]]="Approved",tblEnrollment[[#This Row],[EEP Status]]="Completed",AB11="NPI Match"),"Ready","Not Ready"),"Not Applicable") -> Not Ready | AI11: =IF(tblEnrollment[[#This Row],[Blocked reason]] ="No Blocker","No","Yes") -> Yes
A12: ENR-011 | B12: Summit Eye Care | C12: Dr. Alan Brooks | D12: IND-NPI-1010 | E12: GRP-NPI-9010 | F12: GRP-NPI-9010 | G12: IND-NPI-1010 | H12: SYN-TIN-010 | I12: United Healthacare | J12: UHC01 | K12: Commercial | L12: NA | M12: ERA | N12: Completed | O12: Approved | P12: Rejected | Q12: Yes | R12: Issue Found | S12: 46142 | U12: Blocked | V12: Individual NPI used instead of Group NPI | W12: Nt92346 | X12: 46179 | Y12: ERA rejected due to billing entity mismatch | Z12: =IF(tblEnrollment[[#This Row],[Approved date]]="",DATE(2026,6,3)-tblEnrollment[[#This Row],[Submitted Date]],tblEnrollment[[#This Row],[Approved date]]-tblEnrollment[[#This Row],[Submitted Date]]) -> 34 | AA12: =IF(tblEnrollment[[#This Row],[Current Status]] ="Ready","Completed",IF(Z12>21,"SLA Breached","Within SLA")) -> SLA Breached | AB12: =IF(tblEnrollment[[#This Row],[Credentialed NPI]] =tblEnrollment[[#This Row],[Enrolled NPI]],"NPI Match","NPI Mismatch") -> NPI Mismatch | AC12: =IF(OR(tblEnrollment[[#This Row],[Blocked reason]] ="Individual NPI used instead of Group NPI",tblEnrollment[[#This Row],[Blocked reason]] ="Credentialed NPI mismatch",tblEnrollment[[#This Row],[Blocked reason]] ="Incorrect PTAN/Provider number"),"Yes","No") -> Yes | AD12: =IF(OR(tblEnrollment[[#This Row],[Blocked reason]] ="Wrong Payer ID",tblEnrollment[[#This Row],[Blocked reason]] ="Old Payer ID used"),"Yes","No") -> No | AE12: =IF(OR(tblEnrollment[[#This Row],[EEP updated?]]="No",tblEnrollment[[#This Row],[Blocked reason]] ="Clearinghouse portal not updated"),"Yes","No") -> No | AF12: =IF(OR(tblEnrollment[[#This Row],[Blocked reason]] ="Medicaid additional enrollment is missing",tblEnrollment[[#This Row],[Blocked reason]] ="Incorrect PTAN/Provider number",tblEnrollment[[#This Row],[Blocked reason]] ="Medicare additional enrollment missing"),"Yes","No") -> No | AG12: =IF(OR(tblEnrollment[[#This Row],[Enrollment Type ]]="Claims",tblEnrollment[[#This Row],[Enrollment Type ]]="Claims and ERA"),IF(AND(tblEnrollment[[#This Row],[Credentialing status]]="Completed",tblEnrollment[[#This Row],[Claims_Enrollment_Status]]="Approved",tblEnrollment[[#This Row],[EEP Status]]="Completed",AB12="NPI Match"),"Ready","Not Ready"),"Not Applicable") -> Not Applicable | AH12: =IF(OR(tblEnrollment[[#This Row],[Enrollment Type ]]="ERA",tblEnrollment[[#This Row],[Enrollment Type ]]="Claims and ERA"),IF(AND(tblEnrollment[[#This Row],[Credentialing status]]="Completed",tblEnrollment[[#This Row],[ERA Enrollment Status]]="Approved",tblEnrollment[[#This Row],[EEP Status]]="Completed",AB12="NPI Match"),"Ready","Not Ready"),"Not Applicable") -> Not Ready | AI12: =IF(tblEnrollment[[#This Row],[Blocked reason]] ="No Blocker","No","Yes") -> Yes
A13: ENR-012 | B13: Pine Ridge Family Clinic | C13: Dr. Kavya Iyer | D13: IND-NPI-1011 | E13: GRP-NPI-9011 | F13: GRP-NPI-9011 | G13: GRP-NPI-9011 | H13: SYN-TIN-011 | I13: Aetna | J13: AET01 | K13: Commercial | L13: NA | M13: Claims and ERA | N13: Completed | O13: Pending | P13: Pending | Q13: Yes | R13: In Progress | S13: 46160 | U13: Pending | V13: Missing payer approval | W13: Nt92346 | X13: 46181 | Y13: waiting for payer approval | Z13: =IF(tblEnrollment[[#This Row],[Approved date]]="",DATE(2026,6,3)-tblEnrollment[[#This Row],[Submitted Date]],tblEnrollment[[#This Row],[Approved date]]-tblEnrollment[[#This Row],[Submitted Date]]) -> 16 | AA13: =IF(tblEnrollment[[#This Row],[Current Status]] ="Ready","Completed",IF(Z13>21,"SLA Breached","Within SLA")) -> Within SLA | AB13: =IF(tblEnrollment[[#This Row],[Credentialed NPI]] =tblEnrollment[[#This Row],[Enrolled NPI]],"NPI Match","NPI Mismatch") -> NPI Match | AC13: =IF(OR(tblEnrollment[[#This Row],[Blocked reason]] ="Individual NPI used instead of Group NPI",tblEnrollment[[#This Row],[Blocked reason]] ="Credentialed NPI mismatch",tblEnrollment[[#This Row],[Blocked reason]] ="Incorrect PTAN/Provider number"),"Yes","No") -> No | AD13: =IF(OR(tblEnrollment[[#This Row],[Blocked reason]] ="Wrong Payer ID",tblEnrollment[[#This Row],[Blocked reason]] ="Old Payer ID used"),"Yes","No") -> No | AE13: =IF(OR(tblEnrollment[[#This Row],[EEP updated?]]="No",tblEnrollment[[#This Row],[Blocked reason]] ="Clearinghouse portal not updated"),"Yes","No") -> No | AF13: =IF(OR(tblEnrollment[[#This Row],[Blocked reason]] ="Medicaid additional enrollment is missing",tblEnrollment[[#This Row],[Blocked reason]] ="Incorrect PTAN/Provider number",tblEnrollment[[#This Row],[Blocked reason]] ="Medicare additional enrollment missing"),"Yes","No") -> No | AG13: =IF(OR(tblEnrollment[[#This Row],[Enrollment Type ]]="Claims",tblEnrollment[[#This Row],[Enrollment Type ]]="Claims and ERA"),IF(AND(tblEnrollment[[#This Row],[Credentialing status]]="Completed",tblEnrollment[[#This Row],[Claims_Enrollment_Status]]="Approved",tblEnrollment[[#This Row],[EEP Status]]="Completed",AB13="NPI Match"),"Ready","Not Ready"),"Not Applicable") -> Not Ready | AH13: =IF(OR(tblEnrollment[[#This Row],[Enrollment Type ]]="ERA",tblEnrollment[[#This Row],[Enrollment Type ]]="Claims and ERA"),IF(AND(tblEnrollment[[#This Row],[Credentialing status]]="Completed",tblEnrollment[[#This Row],[ERA Enrollment Status]]="Approved",tblEnrollment[[#This Row],[EEP Status]]="Completed",AB13="NPI Match"),"Ready","Not Ready"),"Not Applicable") -> Not Ready | AI13: =IF(tblEnrollment[[#This Row],[Blocked reason]] ="No Blocker","No","Yes") -> Yes
A14: ENR-013 | B14: Silverline Neurology | C14: Dr. Thomas Gray | D14: IND-NPI-1012 | E14: GRP-NPI-9012 | F14: GRP-NPI-9012 | G14: GRP-NPI-9012 | H14: SYN-TIN-012 | I14: Medicaid | J14: MCD02 | K14: Government | L14: PTAN-012 | M14: Claims | N14: Completed | O14: Approved | P14: Not Required | Q14: Yes | R14: Completed | S14: 46117 | T14: 46133 | U14: Ready | V14: No Blocker | W14: Js19731 | X14: 46176 | Y14: claims enrollment approved | Z14: =IF(tblEnrollment[[#This Row],[Approved date]]="",DATE(2026,6,3)-tblEnrollment[[#This Row],[Submitted Date]],tblEnrollment[[#This Row],[Approved date]]-tblEnrollment[[#This Row],[Submitted Date]]) -> 16 | AA14: =IF(tblEnrollment[[#This Row],[Current Status]] ="Ready","Completed",IF(Z14>21,"SLA Breached","Within SLA")) -> Completed | AB14: =IF(tblEnrollment[[#This Row],[Credentialed NPI]] =tblEnrollment[[#This Row],[Enrolled NPI]],"NPI Match","NPI Mismatch") -> NPI Match | AC14: =IF(OR(tblEnrollment[[#This Row],[Blocked reason]] ="Individual NPI used instead of Group NPI",tblEnrollment[[#This Row],[Blocked reason]] ="Credentialed NPI mismatch",tblEnrollment[[#This Row],[Blocked reason]] ="Incorrect PTAN/Provider number"),"Yes","No") -> No | AD14: =IF(OR(tblEnrollment[[#This Row],[Blocked reason]] ="Wrong Payer ID",tblEnrollment[[#This Row],[Blocked reason]] ="Old Payer ID used"),"Yes","No") -> No | AE14: =IF(OR(tblEnrollment[[#This Row],[EEP updated?]]="No",tblEnrollment[[#This Row],[Blocked reason]] ="Clearinghouse portal not updated"),"Yes","No") -> No | AF14: =IF(OR(tblEnrollment[[#This Row],[Blocked reason]] ="Medicaid additional enrollment is missing",tblEnrollment[[#This Row],[Blocked reason]] ="Incorrect PTAN/Provider number",tblEnrollment[[#This Row],[Blocked reason]] ="Medicare additional enrollment missing"),"Yes","No") -> No | AG14: =IF(OR(tblEnrollment[[#This Row],[Enrollment Type ]]="Claims",tblEnrollment[[#This Row],[Enrollment Type ]]="Claims and ERA"),IF(AND(tblEnrollment[[#This Row],[Credentialing status]]="Completed",tblEnrollment[[#This Row],[Claims_Enrollment_Status]]="Approved",tblEnrollment[[#This Row],[EEP Status]]="Completed",AB14="NPI Match"),"Ready","Not Ready"),"Not Applicable") -> Ready | AH14: =IF(OR(tblEnrollment[[#This Row],[Enrollment Type ]]="ERA",tblEnrollment[[#This Row],[Enrollment Type ]]="Claims and ERA"),IF(AND(tblEnrollment[[#This Row],[Credentialing status]]="Completed",tblEnrollment[[#This Row],[ERA Enrollment Status]]="Approved",tblEnrollment[[#This Row],[EEP Status]]="Completed",AB14="NPI Match"),"Ready","Not Ready"),"Not Applicable") -> Not Applicable | AI14: =IF(tblEnrollment[[#This Row],[Blocked reason]] ="No Blocker","No","Yes") -> No
A15: ENR-014 | B15: Maple Leaf Urgent Care | C15: Dr. Isla Fischer | D15: IND-NPI-1013 | E15: GRP-NPI-9013 | F15: GRP-NPI-9013 | G15: GRP-NPI-9013 | H15: SYN-TIN-013 | I15: Humana | J15: HUM01 | K15: Commercial | L15: NA | M15: Claims and ERA | N15: Completed | O15: Pending | P15: Pending | Q15: No | R15: Pending | S15: 46152 | U15: Pending | V15: Clearinghouse portal not updated | W15: NC00234 | X15: 46179 | Y15: Payer approved but portal route still pending | Z15: =IF(tblEnrollment[[#This Row],[Approved date]]="",DATE(2026,6,3)-tblEnrollment[[#This Row],[Submitted Date]],tblEnrollment[[#This Row],[Approved date]]-tblEnrollment[[#This Row],[Submitted Date]]) -> 24 | AA15: =IF(tblEnrollment[[#This Row],[Current Status]] ="Ready","Completed",IF(Z15>21,"SLA Breached","Within SLA")) -> SLA Breached | AB15: =IF(tblEnrollment[[#This Row],[Credentialed NPI]] =tblEnrollment[[#This Row],[Enrolled NPI]],"NPI Match","NPI Mismatch") -> NPI Match | AC15: =IF(OR(tblEnrollment[[#This Row],[Blocked reason]] ="Individual NPI used instead of Group NPI",tblEnrollment[[#This Row],[Blocked reason]] ="Credentialed NPI mismatch",tblEnrollment[[#This Row],[Blocked reason]] ="Incorrect PTAN/Provider number"),"Yes","No") -> No | AD15: =IF(OR(tblEnrollment[[#This Row],[Blocked reason]] ="Wrong Payer ID",tblEnrollment[[#This Row],[Blocked reason]] ="Old Payer ID used"),"Yes","No") -> No | AE15: =IF(OR(tblEnrollment[[#This Row],[EEP updated?]]="No",tblEnrollment[[#This Row],[Blocked reason]] ="Clearinghouse portal not updated"),"Yes","No") -> Yes | AF15: =IF(OR(tblEnrollment[[#This Row],[Blocked reason]] ="Medicaid additional enrollment is missing",tblEnrollment[[#This Row],[Blocked reason]] ="Incorrect PTAN/Provider number",tblEnrollment[[#This Row],[Blocked reason]] ="Medicare additional enrollment missing"),"Yes","No") -> No | AG15: =IF(OR(tblEnrollment[[#This Row],[Enrollment Type ]]="Claims",tblEnrollment[[#This Row],[Enrollment Type ]]="Claims and ERA"),IF(AND(tblEnrollment[[#This Row],[Credentialing status]]="Completed",tblEnrollment[[#This Row],[Claims_Enrollment_Status]]="Approved",tblEnrollment[[#This Row],[EEP Status]]="Completed",AB15="NPI Match"),"Ready","Not Ready"),"Not Applicable") -> Not Ready | AH15: =IF(OR(tblEnrollment[[#This Row],[Enrollment Type ]]="ERA",tblEnrollment[[#This Row],[Enrollment Type ]]="Claims and ERA"),IF(AND(tblEnrollment[[#This Row],[Credentialing status]]="Completed",tblEnrollment[[#This Row],[ERA Enrollment Status]]="Approved",tblEnrollment[[#This Row],[EEP Status]]="Completed",AB15="NPI Match"),"Ready","Not Ready"),"Not Applicable") -> Not Ready | AI15: =IF(tblEnrollment[[#This Row],[Blocked reason]] ="No Blocker","No","Yes") -> Yes
A16: ENR-015 | B16: Southview endocrinology | C16: Dr. Omar Ali | D16: IND-NPI-1014 | E16: GRP-NPI-9014 | F16: GRP-NPI-9014 | G16: GRP-NPI-9015 | H16: SYN-TIN-014 | I16: Medicare | J16: MED01 | K16: Government | L16: PTAN-014 | M16: Claims and ERA | N16: Completed | O16: Rejected | P16: Rejected | Q16: Yes | R16: Issue Found | S16: 46129 | U16: Blocked | V16: Credentialed NPI mismatch | W16: NC00234 | X16: 46178 | Y16: Wrong group NPI entered during enrollment | Z16: =IF(tblEnrollment[[#This Row],[Approved date]]="",DATE(2026,6,3)-tblEnrollment[[#This Row],[Submitted Date]],tblEnrollment[[#This Row],[Approved date]]-tblEnrollment[[#This Row],[Submitted Date]]) -> 47 | AA16: =IF(tblEnrollment[[#This Row],[Current Status]] ="Ready","Completed",IF(Z16>21,"SLA Breached","Within SLA")) -> SLA Breached | AB16: =IF(tblEnrollment[[#This Row],[Credentialed NPI]] =tblEnrollment[[#This Row],[Enrolled NPI]],"NPI Match","NPI Mismatch") -> NPI Mismatch | AC16: =IF(OR(tblEnrollment[[#This Row],[Blocked reason]] ="Individual NPI used instead of Group NPI",tblEnrollment[[#This Row],[Blocked reason]] ="Credentialed NPI mismatch",tblEnrollment[[#This Row],[Blocked reason]] ="Incorrect PTAN/Provider number"),"Yes","No") -> Yes | AD16: =IF(OR(tblEnrollment[[#This Row],[Blocked reason]] ="Wrong Payer ID",tblEnrollment[[#This Row],[Blocked reason]] ="Old Payer ID used"),"Yes","No") -> No | AE16: =IF(OR(tblEnrollment[[#This Row],[EEP updated?]]="No",tblEnrollment[[#This Row],[Blocked reason]] ="Clearinghouse portal not updated"),"Yes","No") -> No | AF16: =IF(OR(tblEnrollment[[#This Row],[Blocked reason]] ="Medicaid additional enrollment is missing",tblEnrollment[[#This Row],[Blocked reason]] ="Incorrect PTAN/Provider number",tblEnrollment[[#This Row],[Blocked reason]] ="Medicare additional enrollment missing"),"Yes","No") -> No | AG16: =IF(OR(tblEnrollment[[#This Row],[Enrollment Type ]]="Claims",tblEnrollment[[#This Row],[Enrollment Type ]]="Claims and ERA"),IF(AND(tblEnrollment[[#This Row],[Credentialing status]]="Completed",tblEnrollment[[#This Row],[Claims_Enrollment_Status]]="Approved",tblEnrollment[[#This Row],[EEP Status]]="Completed",AB16="NPI Match"),"Ready","Not Ready"),"Not Applicable") -> Not Ready | AH16: =IF(OR(tblEnrollment[[#This Row],[Enrollment Type ]]="ERA",tblEnrollment[[#This Row],[Enrollment Type ]]="Claims and ERA"),IF(AND(tblEnrollment[[#This Row],[Credentialing status]]="Completed",tblEnrollment[[#This Row],[ERA Enrollment Status]]="Approved",tblEnrollment[[#This Row],[EEP Status]]="Completed",AB16="NPI Match"),"Ready","Not Ready"),"Not Applicable") -> Not Ready | AI16: =IF(tblEnrollment[[#This Row],[Blocked reason]] ="No Blocker","No","Yes") -> Yes
A17: ENR-016 | B17: Blue Harbor ENT | C17: Dr. Lily Morgan | D17: IND-NPI-1015 | E17: GRP-NPI-9015 | F17: GRP-NPI-9015 | G17: GRP-NPI-9015 | H17: SYN-TIN-015 | I17: Blue Cross | J17: BLU01 | K17: Commercial | L17: NA | M17: Claims | N17: Completed | O17: Approved | P17: Not Required | Q17: Yes | R17: Completed | S17: 46144 | T17: 46158 | U17: Ready | V17: No Blocker | W17: NC00234 | X17: 46176 | Y17: Ready for claims | Z17: =IF(tblEnrollment[[#This Row],[Approved date]]="",DATE(2026,6,3)-tblEnrollment[[#This Row],[Submitted Date]],tblEnrollment[[#This Row],[Approved date]]-tblEnrollment[[#This Row],[Submitted Date]]) -> 14 | AA17: =IF(tblEnrollment[[#This Row],[Current Status]] ="Ready","Completed",IF(Z17>21,"SLA Breached","Within SLA")) -> Completed | AB17: =IF(tblEnrollment[[#This Row],[Credentialed NPI]] =tblEnrollment[[#This Row],[Enrolled NPI]],"NPI Match","NPI Mismatch") -> NPI Match | AC17: =IF(OR(tblEnrollment[[#This Row],[Blocked reason]] ="Individual NPI used instead of Group NPI",tblEnrollment[[#This Row],[Blocked reason]] ="Credentialed NPI mismatch",tblEnrollment[[#This Row],[Blocked reason]] ="Incorrect PTAN/Provider number"),"Yes","No") -> No | AD17: =IF(OR(tblEnrollment[[#This Row],[Blocked reason]] ="Wrong Payer ID",tblEnrollment[[#This Row],[Blocked reason]] ="Old Payer ID used"),"Yes","No") -> No | AE17: =IF(OR(tblEnrollment[[#This Row],[EEP updated?]]="No",tblEnrollment[[#This Row],[Blocked reason]] ="Clearinghouse portal not updated"),"Yes","No") -> No | AF17: =IF(OR(tblEnrollment[[#This Row],[Blocked reason]] ="Medicaid additional enrollment is missing",tblEnrollment[[#This Row],[Blocked reason]] ="Incorrect PTAN/Provider number",tblEnrollment[[#This Row],[Blocked reason]] ="Medicare additional enrollment missing"),"Yes","No") -> No | AG17: =IF(OR(tblEnrollment[[#This Row],[Enrollment Type ]]="Claims",tblEnrollment[[#This Row],[Enrollment Type ]]="Claims and ERA"),IF(AND(tblEnrollment[[#This Row],[Credentialing status]]="Completed",tblEnrollment[[#This Row],[Claims_Enrollment_Status]]="Approved",tblEnrollment[[#This Row],[EEP Status]]="Completed",AB17="NPI Match"),"Ready","Not Ready"),"Not Applicable") -> Ready | AH17: =IF(OR(tblEnrollment[[#This Row],[Enrollment Type ]]="ERA",tblEnrollment[[#This Row],[Enrollment Type ]]="Claims and ERA"),IF(AND(tblEnrollment[[#This Row],[Credentialing status]]="Completed",tblEnrollment[[#This Row],[ERA Enrollment Status]]="Approved",tblEnrollment[[#This Row],[EEP Status]]="Completed",AB17="NPI Match"),"Ready","Not Ready"),"Not Applicable") -> Not Applicable | AI17: =IF(tblEnrollment[[#This Row],[Blocked reason]] ="No Blocker","No","Yes") -> No
A18: ENR-017 | B18: Valley View Gastro | C18: Dr. Sanjay Mehta | D18: IND-NPI-1016 | E18: GRP-NPI-9016 | F18: GRP-NPI-9016 | G18: GRP-NPI-9016 | H18: SYN-TIN-016 | I18: Cigna | J18: CIG01 | K18: Commercial | L18: NA | M18: ERA | N18: Completed | O18: Approved | P18: Pending | Q18: Yes | R18: In Progress | S18: 46153 | U18: Pending | V18: ERA Setup not completed | W18: Js19731 | X18: 46180 | Y18: ERA pending payer confirmation | Z18: =IF(tblEnrollment[[#This Row],[Approved date]]="",DATE(2026,6,3)-tblEnrollment[[#This Row],[Submitted Date]],tblEnrollment[[#This Row],[Approved date]]-tblEnrollment[[#This Row],[Submitted Date]]) -> 23 | AA18: =IF(tblEnrollment[[#This Row],[Current Status]] ="Ready","Completed",IF(Z18>21,"SLA Breached","Within SLA")) -> SLA Breached | AB18: =IF(tblEnrollment[[#This Row],[Credentialed NPI]] =tblEnrollment[[#This Row],[Enrolled NPI]],"NPI Match","NPI Mismatch") -> NPI Match | AC18: =IF(OR(tblEnrollment[[#This Row],[Blocked reason]] ="Individual NPI used instead of Group NPI",tblEnrollment[[#This Row],[Blocked reason]] ="Credentialed NPI mismatch",tblEnrollment[[#This Row],[Blocked reason]] ="Incorrect PTAN/Provider number"),"Yes","No") -> No | AD18: =IF(OR(tblEnrollment[[#This Row],[Blocked reason]] ="Wrong Payer ID",tblEnrollment[[#This Row],[Blocked reason]] ="Old Payer ID used"),"Yes","No") -> No | AE18: =IF(OR(tblEnrollment[[#This Row],[EEP updated?]]="No",tblEnrollment[[#This Row],[Blocked reason]] ="Clearinghouse portal not updated"),"Yes","No") -> No | AF18: =IF(OR(tblEnrollment[[#This Row],[Blocked reason]] ="Medicaid additional enrollment is missing",tblEnrollment[[#This Row],[Blocked reason]] ="Incorrect PTAN/Provider number",tblEnrollment[[#This Row],[Blocked reason]] ="Medicare additional enrollment missing"),"Yes","No") -> No | AG18: =IF(OR(tblEnrollment[[#This Row],[Enrollment Type ]]="Claims",tblEnrollment[[#This Row],[Enrollment Type ]]="Claims and ERA"),IF(AND(tblEnrollment[[#This Row],[Credentialing status]]="Completed",tblEnrollment[[#This Row],[Claims_Enrollment_Status]]="Approved",tblEnrollment[[#This Row],[EEP Status]]="Completed",AB18="NPI Match"),"Ready","Not Ready"),"Not Applicable") -> Not Applicable | AH18: =IF(OR(tblEnrollment[[#This Row],[Enrollment Type ]]="ERA",tblEnrollment[[#This Row],[Enrollment Type ]]="Claims and ERA"),IF(AND(tblEnrollment[[#This Row],[Credentialing status]]="Completed",tblEnrollment[[#This Row],[ERA Enrollment Status]]="Approved",tblEnrollment[[#This Row],[EEP Status]]="Completed",AB18="NPI Match"),"Ready","Not Ready"),"Not Applicable") -> Not Ready | AI18: =IF(tblEnrollment[[#This Row],[Blocked reason]] ="No Blocker","No","Yes") -> Yes
